<?xml version="1.0" encoding="utf-8"?>
<robot
  name="ymboy-24dof">
  <mujoco>
    <compiler meshdir="../meshes/" discardvisual="false"/>
  </mujoco>
  <link
    name="pelvis">
    <inertial>
      <origin
        xyz="-3.3339E-05 -1.0813E-06 0.091155"
        rpy="0 0 0" />
      <mass
        value="2.8438" />
      <inertia
        ixx="0.01047867"
        ixy="-8E-08"
        ixz="3.95E-06"
        iyy="0.00941324"
        iyz="1.3E-07"
        izz="0.00564707" />
    </inertial>
    <visual>
      <origin
        xyz="0 0 0"
        rpy="0 0 0" />
      <geometry>
        <mesh
          filename="../meshes/pelvis.STL" />
      </geometry>
      <material
        name="">
        <color
          rgba="0.75294 1 1 1" />
      </material>
    </visual>
    <collision>
      <origin
        xyz="0 0 0"
        rpy="0 0 0" />
      <geometry>
        <mesh
          filename="../meshes/pelvis.STL" />
      </geometry>
    </collision>
  </link>
  <link
    name="left_hip_pitch_link">
    <inertial>
      <origin
        xyz="0.0026859 0.030181 -0.038307"
        rpy="0 0 0" />
      <mass
        value="0.47307" />
      <inertia
        ixx="0.00092108"
        ixy="-8.03E-06"
        ixz="8.425E-05"
        iyy="0.00111312"
        iyz="0.0001145"
        izz="0.00048142" />
    </inertial>
    <visual>
      <origin
        xyz="0 0 0"
        rpy="0 0 0" />
      <geometry>
        <mesh
          filename="../meshes/left_hip_pitch_link.STL" />
      </geometry>
      <material
        name="">
        <color
          rgba="0.75294 1 1 1" />
      </material>
    </visual>
    <collision>
      <origin
        xyz="0 0 0"
        rpy="0 0 0" />
      <geometry>
        <mesh
          filename="../meshes/left_hip_pitch_link.STL" />
      </geometry>
    </collision>
  </link>
  <joint
    name="left_hip_pitch_joint"
    type="revolute">
    <origin
      xyz="0 0.056 0.0605"
      rpy="0 0 0" />
    <parent
      link="pelvis" />
    <child
      link="left_hip_pitch_link" />
    <axis
      xyz="0 1 0" />
    <limit
      lower="-2.5"
      upper="2.5"
      effort="94"
      velocity="14" />
  </joint>
  <link
    name="left_hip_roll_link">
    <inertial>
      <origin
        xyz="0.00077985 -7.5152E-06 -0.043617"
        rpy="0 0 0" />
      <mass
        value="1.7024" />
      <inertia
        ixx="0.00593201"
        ixy="-2.4E-07"
        ixz="7.611E-05"
        iyy="0.00560799"
        iyz="-2.1E-07"
        izz="0.00196237" />
    </inertial>
    <visual>
      <origin
        xyz="0 0 0"
        rpy="0 0 0" />
      <geometry>
        <mesh
          filename="../meshes/left_hip_roll_link.STL" />
      </geometry>
      <material
        name="">
        <color
          rgba="0.69804 0.69804 0.69804 1" />
      </material>
    </visual>
    <collision>
      <origin
        xyz="0 0 0"
        rpy="0 0 0" />
      <geometry>
        <mesh
          filename="../meshes/left_hip_roll_link.STL" />
      </geometry>
    </collision>
  </link>
  <joint
    name="left_hip_roll_joint"
    type="revolute">
    <origin
      xyz="0 0.0365 -0.092"
      rpy="0 0 0" />
    <parent
      link="left_hip_pitch_link" />
    <child
      link="left_hip_roll_link" />
    <axis
      xyz="1 0 0" />
    <limit
      lower="-0.5"
      upper="2.5"
      effort="94"
      velocity="14" />
  </joint>
  <link
    name="left_hip_yaw_link">
    <inertial>
      <origin
        xyz="7.7235E-09 -0.00090373 -0.083991"
        rpy="0 0 0" />
      <mass
        value="0.61055" />
      <inertia
        ixx="0.00236125"
        ixy="0"
        ixz="0"
        iyy="0.00202273"
        iyz="6.56E-06"
        izz="0.00073247" />
    </inertial>
    <visual>
      <origin
        xyz="0 0 0"
        rpy="0 0 0" />
      <geometry>
        <mesh
          filename="../meshes/left_hip_yaw_link.STL" />
      </geometry>
      <material
        name="">
        <color
          rgba="0.75294 1 1 1" />
      </material>
    </visual>
    <collision>
      <origin
        xyz="0 0 0"
        rpy="0 0 0" />
      <geometry>
        <mesh
          filename="../meshes/left_hip_yaw_link.STL" />
      </geometry>
    </collision>
  </link>
  <joint
    name="left_hip_yaw_joint"
    type="revolute">
    <origin
      xyz="0.00175 0 -0.1245"
      rpy="0 0 0" />
    <parent
      link="left_hip_roll_link" />
    <child
      link="left_hip_yaw_link" />
    <axis
      xyz="0 0 1" />
    <limit
      lower="-2.5"
      upper="2.5"
      effort="60"
      velocity="14" />
  </joint>
  <link
    name="left_knee_link">
    <inertial>
      <origin
        xyz="-0.0024699 0.00032626 -0.075501"
        rpy="0 0 0" />
      <mass
        value="2.9443" />
      <inertia
        ixx="0.02349646"
        ixy="3.873E-05"
        ixz="-0.00076052"
        iyy="0.02465377"
        iyz="-0.0001571"
        izz="0.00339227" />
    </inertial>
    <visual>
      <origin
        xyz="0 0 0"
        rpy="0 0 0" />
      <geometry>
        <mesh
          filename="../meshes/left_knee_link.STL" />
      </geometry>
      <material
        name="">
        <color
          rgba="0.69804 0.69804 0.69804 1" />
      </material>
    </visual>
    <collision>
      <origin
        xyz="0 0 0"
        rpy="0 0 0" />
      <geometry>
        <mesh
          filename="../meshes/left_knee_link.STL" />
      </geometry>
    </collision>
  </link>
  <joint
    name="left_knee_joint"
    type="revolute">
    <origin
      xyz="0 0 -0.1605"
      rpy="0 0 0" />
    <parent
      link="left_hip_yaw_link" />
    <child
      link="left_knee_link" />
    <axis
      xyz="0 1 0" />
    <limit
      lower="-2.5"
      upper="2.5"
      effort="150"
      velocity="13" />
  </joint>
  <link
    name="left_ankle_pitch_link">
    <inertial>
      <origin
        xyz="-1.1905E-08 -3.0215E-11 -7.7016E-10"
        rpy="0 0 0" />
      <mass
        value="0.023877" />
      <inertia
        ixx="9.56E-06"
        ixy="0"
        ixz="0"
        iyy="6.2E-07"
        iyz="0"
        izz="9.58E-06" />
    </inertial>
    <visual>
      <origin
        xyz="0 0 0"
        rpy="0 0 0" />
      <geometry>
        <mesh
          filename="../meshes/left_ankle_pitch_link.STL" />
      </geometry>
      <material
        name="">
        <color
          rgba="0.75294 1 1 1" />
      </material>
    </visual>
    <!-- <collision>
      <origin
        xyz="0 0 0"
        rpy="0 0 0" />
      <geometry>
        <mesh
          filename="../meshes/left_ankle_pitch_link.STL" />
      </geometry>
    </collision> -->
  </link>
  <joint
    name="left_ankle_pitch_joint"
    type="revolute">
    <origin
      xyz="-4.3311E-05 0 -0.257"
      rpy="0 0.00016853 0" />
    <parent
      link="left_knee_link" />
    <child
      link="left_ankle_pitch_link" />
    <axis
      xyz="0 1 0" />
    <limit
      lower="-0.55"
      upper="0.55"
      effort="60"
      velocity="8" />
  </joint>
  <link
    name="left_ankle_roll_link">
    <inertial>
      <origin
        xyz="0.016184 -9.3563E-10 -0.033038"
        rpy="0 0 0" />
      <mass
        value="1.1614" />
      <inertia
        ixx="0.00090303"
        ixy="0"
        ixz="0.00023861"
        iyy="0.0053827"
        iyz="0"
        izz="0.00583125" />
    </inertial>
    <visual>
      <origin
        xyz="0 0 0"
        rpy="0 0 0" />
      <geometry>
        <mesh
          filename="../meshes/left_ankle_roll_link.STL" />
      </geometry>
      <material
        name="">
        <color
          rgba="0.75294 1 1 1" />
      </material>
    </visual>
    <!-- <collision>
      <origin
        xyz="0 0 0"
        rpy="0 0 0" />
      <geometry>
        <mesh
          filename="../meshes/left_ankle_roll_link.STL" />
      </geometry>
    </collision> -->
    <collision>
      <origin xyz="-0.05 0.05 -0.04" rpy="0 0 0"/>
      <geometry>
        <sphere radius="0.005"/>
      </geometry>
    </collision>
    <collision>
      <origin xyz="-0.05 -0.05 -0.04" rpy="0 0 0"/>
      <geometry>
        <sphere radius="0.005"/>
      </geometry>
    </collision>
    <collision>
      <origin xyz="0.12 0.055 -0.04" rpy="0 0 0"/>
      <geometry>
        <sphere radius="0.005"/>
      </geometry>
    </collision>
    <collision>
      <origin xyz="0.12 -0.055 -0.04" rpy="0 0 0"/>
      <geometry>
        <sphere radius="0.005"/>
      </geometry>
    </collision>
    <collision>
      <origin xyz="0.05 -0.06 -0.04" rpy="0 0 0"/>
      <geometry>
        <sphere radius="0.005"/>
      </geometry>
    </collision>
    <collision>
      <origin xyz="0.05 0.06 -0.04" rpy="0 0 0"/>
      <geometry>
        <sphere radius="0.005"/>
      </geometry>
    </collision>

    <collision>
      <origin xyz="0.14 -0.0 -0.04" rpy="0 0 0"/>
      <geometry>
        <sphere radius="0.005"/>
      </geometry>
    </collision>
    <collision>
      <origin xyz="-0.11 -0.0 -0.04" rpy="0 0 0"/>
      <geometry>
        <sphere radius="0.005"/>
      </geometry>
    </collision>
    <collision>
      <origin xyz="0.1 -0.0 -0.02" rpy="0 0 0"/>
      <geometry>
        <sphere radius="0.005"/>
      </geometry>
    </collision>

    <collision>
      <origin xyz="0.165 -0.0 -0.04" rpy="0 0 0"/>
      <geometry>
        <sphere radius="0.005"/>
      </geometry>
    </collision>
  </link>
  <joint
    name="left_ankle_roll_joint"
    type="revolute">
    <origin
      xyz="0 0 0"
      rpy="0 0 0" />
    <parent
      link="left_ankle_pitch_link" />
    <child
      link="left_ankle_roll_link" />
    <axis
      xyz="1 0 0" />
    <limit
      lower="-0.25"
      upper="0.25"
      effort="60"
      velocity="8" />
  </joint>
  <link
    name="right_hip_pitch_link">
    <inertial>
      <origin
        xyz="0.0026859 -0.030181 -0.038307"
        rpy="0 0 0" />
      <mass
        value="0.47307" />
      <inertia
        ixx="0.00092108"
        ixy="8.03E-06"
        ixz="8.425E-05"
        iyy="0.00111312"
        iyz="-0.0001145"
        izz="0.00048142" />
    </inertial>
    <visual>
      <origin
        xyz="0 0 0"
        rpy="0 0 0" />
      <geometry>
        <mesh
          filename="../meshes/right_hip_pitch_link.STL" />
      </geometry>
      <material
        name="">
        <color
          rgba="0.75294 1 1 1" />
      </material>
    </visual>
    <collision>
      <origin
        xyz="0 0 0"
        rpy="0 0 0" />
      <geometry>
        <mesh
          filename="../meshes/right_hip_pitch_link.STL" />
      </geometry>
    </collision>
  </link>
  <joint
    name="right_hip_pitch_joint"
    type="revolute">
    <origin
      xyz="0 -0.056 0.0605"
      rpy="0 0 0" />
    <parent
      link="pelvis" />
    <child
      link="right_hip_pitch_link" />
    <axis
      xyz="0 1 0" />
    <limit
      lower="-2.5"
      upper="2.5"
      effort="94"
      velocity="14" />
  </joint>
  <link
    name="right_hip_roll_link">
    <inertial>
      <origin
        xyz="0.00077985 -7.5152E-06 -0.043617"
        rpy="0 0 0" />
      <mass
        value="1.7024" />
      <inertia
        ixx="0.00593201"
        ixy="-2.4E-07"
        ixz="7.611E-05"
        iyy="0.00560799"
        iyz="-2.1E-07"
        izz="0.00196237" />
    </inertial>
    <visual>
      <origin
        xyz="0 0 0"
        rpy="0 0 0" />
      <geometry>
        <mesh
          filename="../meshes/right_hip_roll_link.STL" />
      </geometry>
      <material
        name="">
        <color
          rgba="0.75294 1 1 1" />
      </material>
    </visual>
    <collision>
      <origin
        xyz="0 0 0"
        rpy="0 0 0" />
      <geometry>
        <mesh
          filename="../meshes/right_hip_roll_link.STL" />
      </geometry>
    </collision>
  </link>
  <joint
    name="right_hip_roll_joint"
    type="revolute">
    <origin
      xyz="0 -0.0365 -0.092"
      rpy="0 0 0" />
    <parent
      link="right_hip_pitch_link" />
    <child
      link="right_hip_roll_link" />
    <axis
      xyz="1 0 0" />
    <limit
      lower="-2.5"
      upper="0.5"
      effort="94"
      velocity="14" />
  </joint>
  <link
    name="right_hip_yaw_link">
    <inertial>
      <origin
        xyz="7.8127E-09 0.00090374 -0.083991"
        rpy="0 0 0" />
      <mass
        value="0.61055" />
      <inertia
        ixx="0.00236125"
        ixy="0"
        ixz="0"
        iyy="0.00202273"
        iyz="-6.56E-06"
        izz="0.00073247" />
    </inertial>
    <visual>
      <origin
        xyz="0 0 0"
        rpy="0 0 0" />
      <geometry>
        <mesh
          filename="../meshes/right_hip_yaw_link.STL" />
      </geometry>
      <material
        name="">
        <color
          rgba="0.75294 1 1 1" />
      </material>
    </visual>
    <collision>
      <origin
        xyz="0 0 0"
        rpy="0 0 0" />
      <geometry>
        <mesh
          filename="../meshes/right_hip_yaw_link.STL" />
      </geometry>
    </collision>
  </link>
  <joint
    name="right_hip_yaw_joint"
    type="revolute">
    <origin
      xyz="0.00175 0 -0.1245"
      rpy="0 0 0" />
    <parent
      link="right_hip_roll_link" />
    <child
      link="right_hip_yaw_link" />
    <axis
      xyz="0 0 1" />
    <limit
      lower="-2.5"
      upper="2.5"
      effort="60"
      velocity="13" />
  </joint>
  <link
    name="right_knee_link">
    <inertial>
      <origin
        xyz="-0.0024694 -0.00032626 -0.0755"
        rpy="0 0 0" />
      <mass
        value="2.9443" />
      <inertia
        ixx="0.02349561"
        ixy="-3.885E-05"
        ixz="-0.00076039"
        iyy="0.0246529"
        iyz="0.0001571"
        izz="0.00339225" />
    </inertial>
    <visual>
      <origin
        xyz="0 0 0"
        rpy="0 0 0" />
      <geometry>
        <mesh
          filename="../meshes/right_knee_link.STL" />
      </geometry>
      <material
        name="">
        <color
          rgba="0.69804 0.69804 0.69804 1" />
      </material>
    </visual>
    <collision>
      <origin
        xyz="0 0 0"
        rpy="0 0 0" />
      <geometry>
        <mesh
          filename="../meshes/right_knee_link.STL" />
      </geometry>
    </collision>
  </link>
  <joint
    name="right_knee_joint"
    type="revolute">
    <origin
      xyz="0 0 -0.1605"
      rpy="0 0 0" />
    <parent
      link="right_hip_yaw_link" />
    <child
      link="right_knee_link" />
    <axis
      xyz="0 1 0" />
    <limit
      lower="-2.5"
      upper="2.5"
      effort="150"
      velocity="13" />
  </joint>
  <link
    name="right_ankle_pitch_link">
    <inertial>
      <origin
        xyz="-1.1905E-08 -3.0218E-11 -7.7016E-10"
        rpy="0 0 0" />
      <mass
        value="0.023877" />
      <inertia
        ixx="9.56E-06"
        ixy="0"
        ixz="0"
        iyy="6.2E-07"
        iyz="0"
        izz="9.58E-06" />
    </inertial>
    <visual>
      <origin
        xyz="0 0 0"
        rpy="0 0 0" />
      <geometry>
        <mesh
          filename="../meshes/right_ankle_pitch_link.STL" />
      </geometry>
      <material
        name="">
        <color
          rgba="0.75294 1 1 1" />
      </material>
    </visual>
    <!-- <collision>
      <origin
        xyz="0 0 0"
        rpy="0 0 0" />
      <geometry>
        <mesh
          filename="../meshes/right_ankle_pitch_link.STL" />
      </geometry>
    </collision> -->
  </link>
  <joint
    name="right_ankle_pitch_joint"
    type="revolute">
    <origin
      xyz="-4.3311E-05 0 -0.257"
      rpy="0 0.00016853 0" />
    <parent
      link="right_knee_link" />
    <child
      link="right_ankle_pitch_link" />
    <axis
      xyz="0 1 0" />
    <limit
      lower="-0.55"
      upper="0.55"
      effort="60"
      velocity="8" />
  </joint>
  <link
    name="right_ankle_roll_link">
    <inertial>
      <origin
        xyz="0.016184 -9.3564E-10 -0.033038"
        rpy="0 0 0" />
      <mass
        value="1.1614" />
      <inertia
        ixx="0.00090303"
        ixy="0"
        ixz="0.00023861"
        iyy="0.0053827"
        iyz="0"
        izz="0.00583125" />
    </inertial>
    <visual>
      <origin
        xyz="0 0 0"
        rpy="0 0 0" />
      <geometry>
        <mesh
          filename="../meshes/right_ankle_roll_link.STL" />
      </geometry>
      <material
        name="">
        <color
          rgba="0.75294 1 1 1" />
      </material>
    </visual>
    <!-- <collision>
      <origin
        xyz="0 0 0"
        rpy="0 0 0" />
      <geometry>
        <mesh
          filename="../meshes/right_ankle_roll_link.STL" />
      </geometry>
    </collision> -->
    <collision>
      <origin xyz="-0.05 0.05 -0.04" rpy="0 0 0"/>
      <geometry>
        <sphere radius="0.005"/>
      </geometry>
    </collision>
    <collision>
      <origin xyz="-0.05 -0.05 -0.04" rpy="0 0 0"/>
      <geometry>
        <sphere radius="0.005"/>
      </geometry>
    </collision>
    <collision>
      <origin xyz="0.12 0.055 -0.04" rpy="0 0 0"/>
      <geometry>
        <sphere radius="0.005"/>
      </geometry>
    </collision>
    <collision>
      <origin xyz="0.12 -0.055 -0.04" rpy="0 0 0"/>
      <geometry>
        <sphere radius="0.005"/>
      </geometry>
    </collision>
    <collision>
      <origin xyz="0.05 -0.06 -0.04" rpy="0 0 0"/>
      <geometry>
        <sphere radius="0.005"/>
      </geometry>
    </collision>
    <collision>
      <origin xyz="0.05 0.06 -0.04" rpy="0 0 0"/>
      <geometry>
        <sphere radius="0.005"/>
      </geometry>
    </collision>

    <collision>
      <origin xyz="0.14 -0.0 -0.04" rpy="0 0 0"/>
      <geometry>
        <sphere radius="0.005"/>
      </geometry>
    </collision>
    <collision>
      <origin xyz="-0.11 -0.0 -0.04" rpy="0 0 0"/>
      <geometry>
        <sphere radius="0.005"/>
      </geometry>
    </collision>
    <collision>
      <origin xyz="0.1 -0.0 -0.02" rpy="0 0 0"/>
      <geometry>
        <sphere radius="0.005"/>
      </geometry>
    </collision>

    <collision>
      <origin xyz="0.165 -0.0 -0.04" rpy="0 0 0"/>
      <geometry>
        <sphere radius="0.005"/>
      </geometry>
    </collision>
  </link>
  <joint
    name="right_ankle_roll_joint"
    type="revolute">
    <origin
      xyz="0 0 0"
      rpy="0 0 0" />
    <parent
      link="right_ankle_pitch_link" />
    <child
      link="right_ankle_roll_link" />
    <axis
      xyz="1 0 0" />
    <limit
      lower="-0.25"
      upper="0.25"
      effort="60"
      velocity="8" />
  </joint>
  <link
    name="waist_yaw_link">
    <inertial>
      <origin
        xyz="-8.6742E-09 -0.0035731 0.038467"
        rpy="0 0 0" />
      <mass
        value="0.33855" />
      <inertia
        ixx="0.00059365"
        ixy="0"
        ixz="0"
        iyy="0.00038188"
        iyz="5.297E-05"
        izz="0.00041589" />
    </inertial>
    <visual>
      <origin
        xyz="0 0 0"
        rpy="0 0 0" />
      <geometry>
        <mesh
          filename="../meshes/waist_yaw_link.STL" />
      </geometry>
      <material
        name="">
        <color
          rgba="0.75294 1 1 1" />
      </material>
    </visual>
    <collision>
      <origin
        xyz="0 0 0"
        rpy="0 0 0" />
      <geometry>
        <mesh
          filename="../meshes/waist_yaw_link.STL" />
      </geometry>
    </collision>
  </link>
  <joint
    name="waist_yaw_joint"
    type="revolute">
    <origin
      xyz="0 0 0.177"
      rpy="0 0 0" />
    <parent
      link="pelvis" />
    <child
      link="waist_yaw_link" />
    <axis
      xyz="0 0 1" />
    <limit
      lower="-2.5"
      upper="2.5"
      effort="94"
      velocity="14" />
  </joint>
  <link
    name="torso_link">
    <inertial>
      <origin
        xyz="-0.0028374 1.8764E-05 0.11742"
        rpy="0 0 0" />
      <mass
        value="8.4343" />
      <inertia
        ixx="0.05386501"
        ixy="5.861E-05"
        ixz="-0.00096421"
        iyy="0.04829131"
        iyz="-0.00014315"
        izz="0.03221841" />
    </inertial>
    <visual>
      <origin
        xyz="0 0 0"
        rpy="0 0 0" />
      <geometry>
        <mesh
          filename="../meshes/torso_link.STL" />
      </geometry>
      <material
        name="">
        <color
          rgba="0.69804 0.69804 0.69804 1" />
      </material>
    </visual>
    <collision>
      <origin
        xyz="0 0 0"
        rpy="0 0 0" />
      <geometry>
        <mesh
          filename="../meshes/torso_link.STL" />
      </geometry>
    </collision>
  </link>
  <joint
    name="waist_pitch_joint"
    type="revolute">
    <origin
      xyz="0 0 0.069"
      rpy="0 0 0" />
    <parent
      link="waist_yaw_link" />
    <child
      link="torso_link" />
    <axis
      xyz="0 1 0" />
    <limit
      lower="-1.57"
      upper="1.57"
      effort="94"
      velocity="14" />
  </joint>
  <link
    name="left_shoulder_pitch_link">
    <inertial>
      <origin
        xyz="0.021414 0.043756 -7.7846E-11"
        rpy="0 0 0" />
      <mass
        value="0.48864" />
      <inertia
        ixx="0.00016103"
        ixy="-3.426E-05"
        ixz="0"
        iyy="9.344E-05"
        iyz="0"
        izz="0.00014485" />
    </inertial>
    <visual>
      <origin
        xyz="0 0 0"
        rpy="0 0 0" />
      <geometry>
        <mesh
          filename="../meshes/left_shoulder_pitch_link.STL" />
      </geometry>
      <material
        name="">
        <color
          rgba="0.75294 1 1 1" />
      </material>
    </visual>
    <collision>
      <origin
        xyz="0 0 0"
        rpy="0 0 0" />
      <geometry>
        <mesh
          filename="../meshes/left_shoulder_pitch_link.STL" />
      </geometry>
    </collision>
  </link>
  <joint
    name="left_shoulder_pitch_joint"
    type="revolute">
    <origin
      xyz="0 0.12875 0.1945"
      rpy="0 0 0" />
    <parent
      link="torso_link" />
    <child
      link="left_shoulder_pitch_link" />
    <axis
      xyz="0 1 0" />
    <limit
      lower="-2.57"
      upper="2.57"
      effort="12"
      velocity="5" />
  </joint>
  <link
    name="left_shoulder_roll_link">
    <inertial>
      <origin
        xyz="2.2968E-15 0.0016422 -0.019214"
        rpy="0 0 0" />
      <mass
        value="0.053968" />
      <inertia
        ixx="1.8069E-05"
        ixy="2.8391E-20"
        ixz="1.641E-20"
        iyy="4.6417E-05"
        iyz="-9.6777E-07"
        izz="4.1079E-05" />
    </inertial>
    <visual>
      <origin
        xyz="0 0 0"
        rpy="0 0 0" />
      <geometry>
        <mesh
          filename="../meshes/left_shoulder_roll_link.STL" />
      </geometry>
      <material
        name="">
        <color
          rgba="0.75294 1 1 1" />
      </material>
    </visual>
    <collision>
      <origin
        xyz="0 0 0"
        rpy="0 0 0" />
      <geometry>
        <mesh
          filename="../meshes/left_shoulder_roll_link.STL" />
      </geometry>
    </collision>
  </link>
  <joint
    name="left_shoulder_roll_joint"
    type="revolute">
    <origin
      xyz="0 0.047 0"
      rpy="0 0 0" />
    <parent
      link="left_shoulder_pitch_link" />
    <child
      link="left_shoulder_roll_link" />
    <axis
      xyz="1 0 0" />
    <limit
      lower="-0.1"
      upper="3.14"
      effort="12"
      velocity="5" />
  </joint>
  <link
    name="left_shoulder_yaw_link">
    <inertial>
      <origin
        xyz="2.3458E-05 0.010492 -0.079775"
        rpy="0 0 0" />
      <mass
        value="0.99729" />
      <inertia
        ixx="0.00221488"
        ixy="2.4E-07"
        ixz="-6.2E-07"
        iyy="0.00211341"
        iyz="0.00046727"
        izz="0.00040755" />
    </inertial>
    <visual>
      <origin
        xyz="0 0 0"
        rpy="0 0 0" />
      <geometry>
        <mesh
          filename="../meshes/left_shoulder_yaw_link.STL" />
      </geometry>
      <material
        name="">
        <color
          rgba="0.8549 0.80392 0.52941 1" />
      </material>
    </visual>
    <collision>
      <origin
        xyz="0 0 0"
        rpy="0 0 0" />
      <geometry>
        <mesh
          filename="../meshes/left_shoulder_yaw_link.STL" />
      </geometry>
    </collision>
  </link>
  <joint
    name="left_shoulder_yaw_joint"
    type="revolute">
    <origin
      xyz="0 0.007 -0.033"
      rpy="0 0 0" />
    <parent
      link="left_shoulder_roll_link" />
    <child
      link="left_shoulder_yaw_link" />
    <axis
      xyz="0 0 1" />
    <limit
      lower="-2.57"
      upper="2.57"
      effort="12"
      velocity="5" />
  </joint>
  <link
    name="left_elbow_link">
    <inertial>
      <origin
        xyz="0 8.3267E-17 -0.02168"
        rpy="0 0 0" />
      <mass
        value="0.047607" />
      <inertia
        ixx="3.565E-05"
        ixy="3.661E-21"
        ixz="3.9684E-21"
        iyy="1.1477E-05"
        iyz="6.8173E-20"
        izz="3.3394E-05" />
    </inertial>
    <visual>
      <origin
        xyz="0 0 0"
        rpy="0 0 0" />
      <geometry>
        <mesh
          filename="../meshes/left_elbow_link.STL" />
      </geometry>
      <material
        name="">
        <color
          rgba="0.75294 1 1 1" />
      </material>
    </visual>
    <collision>
      <origin
        xyz="0 0 0"
        rpy="0 0 0" />
      <geometry>
        <mesh
          filename="../meshes/left_elbow_link.STL" />
      </geometry>
    </collision>
  </link>
  <joint
    name="left_elbow_joint"
    type="revolute">
    <origin
      xyz="0 0 -0.1244"
      rpy="0 0 0" />
    <parent
      link="left_shoulder_yaw_link" />
    <child
      link="left_elbow_link" />
    <axis
      xyz="0 1 0" />
    <limit
      lower="-2"
      upper="2"
      effort="12"
      velocity="5" />
  </joint>
  <link
    name="left_wrist_yaw_link">
    <inertial>
      <origin
        xyz="-1.211E-08 0.0015412 -0.095114"
        rpy="0 0 0" />
      <mass
        value="0.74918" />
      <inertia
        ixx="0.00235166"
        ixy="0"
        ixz="1.17E-06"
        iyy="0.00234442"
        iyz="6.14E-06"
        izz="0.00018441" />
    </inertial>
    <visual>
      <origin
        xyz="0 0 0"
        rpy="0 0 0" />
      <geometry>
        <mesh
          filename="../meshes/left_wrist_yaw_link.STL" />
      </geometry>
      <material
        name="">
        <color
          rgba="0.69804 0.69804 0.69804 1" />
      </material>
    </visual>
    <collision>
      <origin
        xyz="0 0 0"
        rpy="0 0 0" />
      <geometry>
        <mesh
          filename="../meshes/left_wrist_yaw_link.STL" />
      </geometry>
    </collision>
  </link>
  <joint
    name="left_wrist_yaw_joint"
    type="revolute">
    <origin
      xyz="0 0 -0.034"
      rpy="0 0 0" />
    <parent
      link="left_elbow_link" />
    <child
      link="left_wrist_yaw_link" />
    <axis
      xyz="0 0 1" />
    <limit
      lower="-2.57"
      upper="2.57"
      effort="6"
      velocity="5" />
  </joint>
  <link
    name="right_shoulder_pitch_link">
    <inertial>
      <origin
        xyz="-0.021414 -0.043756 -7.7846E-11"
        rpy="0 0 0" />
      <mass
        value="0.48864" />
      <inertia
        ixx="0.00016103"
        ixy="-3.426E-05"
        ixz="0"
        iyy="9.344E-05"
        iyz="0"
        izz="0.00014485" />
    </inertial>
    <visual>
      <origin
        xyz="0 0 0"
        rpy="0 0 0" />
      <geometry>
        <mesh
          filename="../meshes/right_shoulder_pitch_link.STL" />
      </geometry>
      <material
        name="">
        <color
          rgba="0.75294 1 1 1" />
      </material>
    </visual>
    <collision>
      <origin
        xyz="0 0 0"
        rpy="0 0 0" />
      <geometry>
        <mesh
          filename="../meshes/right_shoulder_pitch_link.STL" />
      </geometry>
    </collision>
  </link>
  <joint
    name="right_shoulder_pitch_joint"
    type="revolute">
    <origin
      xyz="0 -0.12875 0.1945"
      rpy="0 0 0" />
    <parent
      link="torso_link" />
    <child
      link="right_shoulder_pitch_link" />
    <axis
      xyz="0 1 0" />
     <limit
      lower="-2.57"
      upper="2.57"
      effort="12"
      velocity="5" />
  </joint>
  <link
    name="right_shoulder_roll_link">
    <inertial>
      <origin
        xyz="1.1102E-16 -0.0016422 -0.019214"
        rpy="0 0 0" />
      <mass
        value="0.053968" />
      <inertia
        ixx="1.8069E-05"
        ixy="1.0344E-21"
        ixz="6.3703E-20"
        iyy="4.6417E-05"
        iyz="9.6777E-07"
        izz="4.1079E-05" />
    </inertial>
    <visual>
      <origin
        xyz="0 0 0"
        rpy="0 0 0" />
      <geometry>
        <mesh
          filename="../meshes/right_shoulder_roll_link.STL" />
      </geometry>
      <material
        name="">
        <color
          rgba="0.75294 1 1 1" />
      </material>
    </visual>
    <collision>
      <origin
        xyz="0 0 0"
        rpy="0 0 0" />
      <geometry>
        <mesh
          filename="../meshes/right_shoulder_roll_link.STL" />
      </geometry>
    </collision>
  </link>
  <joint
    name="right_shoulder_roll_joint"
    type="revolute">
    <origin
      xyz="0 -0.047 0"
      rpy="0 0 0" />
    <parent
      link="right_shoulder_pitch_link" />
    <child
      link="right_shoulder_roll_link" />
    <axis
      xyz="1 0 0" />
    <limit
      lower="-3.14"
      upper="0.1"
      effort="12"
      velocity="5" />
  </joint>
  <link
    name="right_shoulder_yaw_link">
    <inertial>
      <origin
        xyz="-2.3457E-05 0.010492 -0.079775"
        rpy="0 0 0" />
      <mass
        value="0.99729" />
      <inertia
        ixx="0.00221488"
        ixy="-2.5E-07"
        ixz="6.2E-07"
        iyy="0.00211341"
        iyz="0.00046727"
        izz="0.00040755" />
    </inertial>
    <visual>
      <origin
        xyz="0 0 0"
        rpy="0 0 0" />
      <geometry>
        <mesh
          filename="../meshes/right_shoulder_yaw_link.STL" />
      </geometry>
      <material
        name="">
        <color
          rgba="0.8549 0.80392 0.52941 1" />
      </material>
    </visual>
    <collision>
      <origin
        xyz="0 0 0"
        rpy="0 0 0" />
      <geometry>
        <mesh
          filename="../meshes/right_shoulder_yaw_link.STL" />
      </geometry>
    </collision>
  </link>
  <joint
    name="right_shoulder_yaw_joint"
    type="revolute">
    <origin
      xyz="0 -0.007 -0.033"
      rpy="0 0 0" />
    <parent
      link="right_shoulder_roll_link" />
    <child
      link="right_shoulder_yaw_link" />
    <axis
      xyz="0 0 1" />
    <limit
      lower="-2.57"
      upper="2.57"
      effort="12"
      velocity="5" />
  </joint>
  <link
    name="right_elbow_link">
    <inertial>
      <origin
        xyz="-4.8572E-17 0 -0.02168"
        rpy="0 0 0" />
      <mass
        value="0.047607" />
      <inertia
        ixx="3.565E-05"
        ixy="1.3905E-21"
        ixz="3.189E-21"
        iyy="1.1477E-05"
        iyz="-1.6076E-20"
        izz="3.3394E-05" />
    </inertial>
    <visual>
      <origin
        xyz="0 0 0"
        rpy="0 0 0" />
      <geometry>
        <mesh
          filename="../meshes/right_elbow_link.STL" />
      </geometry>
      <material
        name="">
        <color
          rgba="0.75294 1 1 1" />
      </material>
    </visual>
    <collision>
      <origin
        xyz="0 0 0"
        rpy="0 0 0" />
      <geometry>
        <mesh
          filename="../meshes/right_elbow_link.STL" />
      </geometry>
    </collision>
  </link>
  <joint
    name="right_elbow_joint"
    type="revolute">
    <origin
      xyz="0 0 -0.1244"
      rpy="0 0 0" />
    <parent
      link="right_shoulder_yaw_link" />
    <child
      link="right_elbow_link" />
    <axis
      xyz="0 1 0" />
    <limit
      lower="-2"
      upper="2"
      effort="12"
      velocity="5" />
  </joint>
  <link
    name="right_wrist_yaw_link">
    <inertial>
      <origin
        xyz="-1.211E-08 0.0015412 -0.095114"
        rpy="0 0 0" />
      <mass
        value="0.74918" />
      <inertia
        ixx="0.00235166"
        ixy="0"
        ixz="1.17E-06"
        iyy="0.00234442"
        iyz="6.14E-06"
        izz="0.00018441" />
    </inertial>
    <visual>
      <origin
        xyz="0 0 0"
        rpy="0 0 0" />
      <geometry>
        <mesh
          filename="../meshes/right_wrist_yaw_link.STL" />
      </geometry>
      <material
        name="">
        <color
          rgba="0.69804 0.69804 0.69804 1" />
      </material>
    </visual>
    <collision>
      <origin
        xyz="0 0 0"
        rpy="0 0 0" />
      <geometry>
        <mesh
          filename="../meshes/right_wrist_yaw_link.STL" />
      </geometry>
    </collision>
  </link>
  <joint
    name="right_wrist_yaw_joint"
    type="revolute">
    <origin
      xyz="0 0 -0.034"
      rpy="0 0 0" />
    <parent
      link="right_elbow_link" />
    <child
      link="right_wrist_yaw_link" />
    <axis
      xyz="0 0 1" />
    <limit
      lower="-2.57"
      upper="2.57"
      effort="6"
      velocity="5" />
  </joint>

  <!-- Keyframe -->
  <link name="keyframe_head_link">
    <!-- <visual>
      <origin xyz="0 0 0" rpy="0 0 0"/>
      <geometry>
        <sphere radius="0.05"/>
      </geometry>
    </visual> -->
  </link>
  <joint name="keyframe_head_joint" type="fixed" dont_collapse="true">
    <origin xyz="0 0 0.45" rpy="0 0 0"/>
    <parent link="torso_link"/>
    <child link="keyframe_head_link"/>
  </joint>
  <link name="keyframe_torso_link">
    <!-- <visual>
      <origin xyz="0 0 0" rpy="0 0 0"/>
      <geometry>
        <sphere radius="0.05"/>
      </geometry>
    </visual> -->
  </link>
  <joint name="keyframe_torso_joint" type="fixed" dont_collapse="true">
    <origin xyz="0 0 0.2" rpy="0 0 0"/>
    <parent link="torso_link"/>
    <child link="keyframe_torso_link"/>
  </joint>
  <link name="keyframe_pelvis_link">
    <!-- <visual>
      <origin xyz="0 0 0" rpy="0 0 0"/>
      <geometry>
        <sphere radius="0.05"/>
      </geometry>
    </visual> -->
  </link>
  <joint name="keyframe_pelvis_joint" type="fixed" dont_collapse="true">
    <origin xyz="0 0 -0.075" rpy="0 0 0"/>
    <parent link="pelvis"/>
    <child link="keyframe_pelvis_link"/>
  </joint>



  <link name="keyframe_left_collar_link">
    <!-- <visual>
      <origin xyz="0 0 0" rpy="0 0 0"/>
      <geometry>
        <sphere radius="0.05"/>
      </geometry>
    </visual> -->
  </link>
  <joint name="keyframe_left_collar_joint" type="fixed" dont_collapse="true">
    <origin xyz="0 0 0.02" rpy="0 0 0"/>
    <parent link="left_shoulder_pitch_link"/>
    <child link="keyframe_left_collar_link"/>
  </joint>
  <link name="keyframe_right_collar_link">
    <!-- <visual>
      <origin xyz="0 0 0" rpy="0 0 0"/>
      <geometry>
        <sphere radius="0.05"/>
      </geometry>
    </visual> -->
  </link>
  <joint name="keyframe_right_collar_joint" type="fixed" dont_collapse="true">
    <origin xyz="0 0 0.02" rpy="0 0 0"/>
    <parent link="right_shoulder_pitch_link"/>
    <child link="keyframe_right_collar_link"/>
  </joint>

  <link name="keyframe_left_shoulder_link">
    <!-- <visual>
      <origin xyz="0 0 0" rpy="0 0 0"/>
      <geometry>
        <sphere radius="0.05"/>
      </geometry>
    </visual> -->
  </link>
  <joint name="keyframe_left_shoulder_joint" type="fixed" dont_collapse="true">
    <origin xyz="0 0 0" rpy="0 0 0"/>
    <parent link="left_shoulder_roll_link"/>
    <child link="keyframe_left_shoulder_link"/>
  </joint>
  <link name="keyframe_right_shoulder_link">
    <!-- <visual>
      <origin xyz="0 0 0" rpy="0 0 0"/>
      <geometry>
        <sphere radius="0.05"/>
      </geometry>
    </visual> -->
  </link>
  <joint name="keyframe_right_shoulder_joint" type="fixed" dont_collapse="true">
    <origin xyz="0 0 0" rpy="0 0 0"/>
    <parent link="right_shoulder_roll_link"/>
    <child link="keyframe_right_shoulder_link"/>
  </joint>
  <link name="keyframe_left_elbow_link">
    <!-- <visual>
      <origin xyz="0 0 0" rpy="0 0 0"/>
      <geometry>
        <sphere radius="0.05"/>
      </geometry>
    </visual> -->
  </link>
  <joint name="keyframe_left_elbow_joint" type="fixed" dont_collapse="true">
    <origin xyz="0 0 0" rpy="0 0 0"/>
    <parent link="left_elbow_link"/>
    <child link="keyframe_left_elbow_link"/>
  </joint>
  <link name="keyframe_right_elbow_link">
    <!-- <visual>
      <origin xyz="0 0 0" rpy="0 0 0"/>
      <geometry>
        <sphere radius="0.05"/>
      </geometry>
    </visual> -->
  </link>
  <joint name="keyframe_right_elbow_joint" type="fixed" dont_collapse="true">
    <origin xyz="0 0 0" rpy="0 0 0"/>
    <parent link="right_elbow_link"/>
    <child link="keyframe_right_elbow_link"/>
  </joint>

  <link name="keyframe_left_wrist_link">
    <!-- <visual>
      <origin xyz="0 0 0" rpy="0 0 0"/>
      <geometry>
        <sphere radius="0.05"/>
      </geometry>
    </visual> -->
  </link>
  <joint name="keyframe_left_wrist_joint" type="fixed" dont_collapse="true">
    <origin xyz="0 0 0" rpy="0 0 0"/>
    <parent link="left_wrist_yaw_link"/>
    <child link="keyframe_left_wrist_link"/>
  </joint>
  <link name="keyframe_right_wrist_link">
    <!-- <visual>
      <origin xyz="0 0 0" rpy="0 0 0"/>
      <geometry>
        <sphere radius="0.05"/>
      </geometry>
    </visual> -->
  </link>
  <joint name="keyframe_right_wrist_joint" type="fixed" dont_collapse="true">
    <origin xyz="0 0 0" rpy="0 0 0"/>
    <parent link="right_wrist_yaw_link"/>
    <child link="keyframe_right_wrist_link"/>
  </joint>

  <link name="keyframe_left_hip_link">
    <!-- <visual>
      <origin xyz="0 0 0" rpy="0 0 0"/>
      <geometry>
        <sphere radius="0.05"/>
      </geometry>
    </visual> -->
  </link>
  <joint name="keyframe_left_hip_joint" type="fixed" dont_collapse="true">
    <origin xyz="0 0 0" rpy="0 0 0"/>
    <parent link="left_hip_roll_link"/>
    <child link="keyframe_left_hip_link"/>
  </joint>
  <link name="keyframe_right_hip_link">
    <!-- <visual>
      <origin xyz="0 0 0" rpy="0 0 0"/>
      <geometry>
        <sphere radius="0.05"/>
      </geometry>
    </visual> -->
  </link>
  <joint name="keyframe_right_hip_joint" type="fixed" dont_collapse="true">
    <origin xyz="0 0 0" rpy="0 0 0"/>
    <parent link="right_hip_roll_link"/>
    <child link="keyframe_right_hip_link"/>
  </joint>
  <link name="keyframe_left_knee_link">
    <!-- <visual>
      <origin xyz="0 0 0" rpy="0 0 0"/>
      <geometry>
        <sphere radius="0.05"/>
      </geometry>
    </visual> -->
  </link>
  <joint name="keyframe_left_knee_joint" type="fixed" dont_collapse="true">
    <origin xyz="0 0 0" rpy="0 0 0"/>
    <parent link="left_knee_link"/>
    <child link="keyframe_left_knee_link"/>
  </joint>
  <link name="keyframe_right_knee_link">
    <!-- <visual>
      <origin xyz="0 0 0" rpy="0 0 0"/>
      <geometry>
        <sphere radius="0.05"/>
      </geometry>
    </visual> -->
  </link>
  <joint name="keyframe_right_knee_joint" type="fixed" dont_collapse="true">
    <origin xyz="0 0 0" rpy="0 0 0"/>
    <parent link="right_knee_link"/>
    <child link="keyframe_right_knee_link"/>
  </joint>
  <link name="keyframe_left_ankle_link">
    <!-- <visual>
      <origin xyz="0 0 0" rpy="0 0 0"/>
      <geometry>
        <sphere radius="0.05"/>
      </geometry>
    </visual> -->
  </link>
  <joint name="keyframe_left_ankle_joint" type="fixed" dont_collapse="true">
    <origin xyz="0 0 0" rpy="0 0 0"/>
    <parent link="left_ankle_roll_link"/>
    <child link="keyframe_left_ankle_link"/>
  </joint>
  <link name="keyframe_right_ankle_link">
    <!-- <visual>
      <origin xyz="0 0 0" rpy="0 0 0"/>
      <geometry>
        <sphere radius="0.05"/>
      </geometry>
    </visual> -->
  </link>
  <joint name="keyframe_right_ankle_joint" type="fixed" dont_collapse="true">
    <origin xyz="0 0 0" rpy="0 0 0"/>
    <parent link="right_ankle_roll_link"/>
    <child link="keyframe_right_ankle_link"/>
  </joint>


  <!-- Auxiliary -->
  <link name="auxiliary_right_ankle_roll_link1">
    <visual>
      <origin xyz="0 0 0" rpy="0 0 0"/>
      <geometry>
        <sphere radius="0.01"/>
      </geometry>
    </visual>
  </link>
  <joint name="auxiliary_right_ankle_roll_joint1" type="fixed" dont_collapse="true">
    <origin xyz="0.035 0.08 0" rpy="0 0 0"/>
    <parent link="right_ankle_roll_link"/>
    <child link="auxiliary_right_ankle_roll_link1"/>
  </joint>
  <link name="auxiliary_right_ankle_roll_link2">
    <visual>
      <origin xyz="0 0 0" rpy="0 0 0"/>
      <geometry>
        <sphere radius="0.01"/>
      </geometry>
    </visual>
  </link>
  <joint name="auxiliary_right_ankle_roll_joint2" type="fixed" dont_collapse="true">
    <origin xyz="0.035 -0.08 0" rpy="0 0 0"/>
    <parent link="right_ankle_roll_link"/>
    <child link="auxiliary_right_ankle_roll_link2"/>
  </joint>

  <link name="auxiliary_right_ankle_roll_link3">
    <visual>
      <origin xyz="0 0 0" rpy="0 0 0"/>
      <geometry>
        <sphere radius="0.01"/>
      </geometry>
    </visual>
  </link>
  <joint name="auxiliary_right_ankle_roll_joint3" type="fixed" dont_collapse="true">
    <origin xyz="0.2 0 0" rpy="0 0 0"/>
    <parent link="right_ankle_roll_link"/>
    <child link="auxiliary_right_ankle_roll_link3"/>
  </joint>
  <link name="auxiliary_right_ankle_roll_link4">
    <visual>
      <origin xyz="0 0 0" rpy="0 0 0"/>
      <geometry>
        <sphere radius="0.01"/>
      </geometry>
    </visual>
  </link>
  <joint name="auxiliary_right_ankle_roll_joint4" type="fixed" dont_collapse="true">
    <origin xyz="-0.15 0 0" rpy="0 0 0"/>
    <parent link="right_ankle_roll_link"/>
    <child link="auxiliary_right_ankle_roll_link4"/>
  </joint>

  <link name="auxiliary_left_ankle_roll_link1">
    <visual>
      <origin xyz="0 0 0" rpy="0 0 0"/>
      <geometry>
        <sphere radius="0.01"/>
      </geometry>
    </visual>
  </link>
  <joint name="auxiliary_left_ankle_roll_joint1" type="fixed" dont_collapse="true">
    <origin xyz="0.035 0.08 0" rpy="0 0 0"/>
    <parent link="left_ankle_roll_link"/>
    <child link="auxiliary_left_ankle_roll_link1"/>
  </joint>
  <link name="auxiliary_left_ankle_roll_link2">
    <visual>
      <origin xyz="0 0 0" rpy="0 0 0"/>
      <geometry>
        <sphere radius="0.01"/>
      </geometry>
    </visual>
  </link>
  <joint name="auxiliary_left_ankle_roll_joint2" type="fixed" dont_collapse="true">
    <origin xyz="0.035 -0.08 0" rpy="0 0 0"/>
    <parent link="left_ankle_roll_link"/>
    <child link="auxiliary_left_ankle_roll_link2"/>
  </joint>

  <link name="auxiliary_left_ankle_roll_link3">
    <visual>
      <origin xyz="0 0 0" rpy="0 0 0"/>
      <geometry>
        <sphere radius="0.01"/>
      </geometry>
    </visual>
  </link>
  <joint name="auxiliary_left_ankle_roll_joint3" type="fixed" dont_collapse="true">
    <origin xyz="0.2 0 0" rpy="0 0 0"/>
    <parent link="left_ankle_roll_link"/>
    <child link="auxiliary_left_ankle_roll_link3"/>
  </joint>
  <link name="auxiliary_left_ankle_roll_link4">
    <visual>
      <origin xyz="0 0 0" rpy="0 0 0"/>
      <geometry>
        <sphere radius="0.01"/>
      </geometry>
    </visual>
  </link>
  <joint name="auxiliary_left_ankle_roll_joint4" type="fixed" dont_collapse="true">
    <origin xyz="-0.15 0 0" rpy="0 0 0"/>
    <parent link="left_ankle_roll_link"/>
    <child link="auxiliary_left_ankle_roll_link4"/>
  </joint>

  <link name="left_foot_front_link" />
  <joint name="left_foot_front_joint" type="fixed" dont_collapse="true">
    <origin xyz="0.18 0 -0.06" rpy="0 0 0" />
    <parent link="left_ankle_pitch_link" />
    <child link="left_foot_front_link" />
  </joint>

  <link name="left_foot_mid_link" />
  <joint name="left_foot_mid_joint" type="fixed" dont_collapse="true">
    <origin xyz="0.0 0 -0.06" rpy="0 0 0" />
    <parent link="left_ankle_pitch_link" />
    <child link="left_foot_mid_link" />
  </joint>

  <link name="left_foot_hind_link" />
  <joint name="left_foot_hind_joint" type="fixed" dont_collapse="true">
    <origin xyz="-0.09 0 -0.06" rpy="0 0 0" />
    <parent link="left_ankle_pitch_link" />
    <child link="left_foot_hind_link" />
  </joint>

  <link name="right_foot_front_link" />
  <joint name="right_foot_front_joint" type="fixed" dont_collapse="true">
    <origin xyz="0.18 0 -0.06" rpy="0 0 0" />
    <parent link="right_ankle_pitch_link" />
    <child link="right_foot_front_link" />
  </joint>

  <link name="right_foot_mid_link" />
  <joint name="right_foot_mid_joint" type="fixed" dont_collapse="true">
    <origin xyz="0.0 0 -0.06" rpy="0 0 0" />
    <parent link="right_ankle_pitch_link" />
    <child link="right_foot_mid_link" />
  </joint>

  <link name="right_foot_hind_link" />
  <joint name="right_foot_hind_joint" type="fixed" dont_collapse="true">
    <origin xyz="-0.09 0 -0.06" rpy="0 0 0" />
    <parent link="right_ankle_pitch_link" />
    <child link="right_foot_hind_link" />
  </joint>

</robot>