<mujoco model="ymboy-23dof">
    <compiler angle="radian" meshdir="../meshes"/>
    <statistic meansize="0.144785" extent="1.23314" center="0.025392 2.0634e-05 -0.245975"/>
    <default>
      <joint damping="0.001" armature="0.01" frictionloss="0.1"/>
    </default>
    <asset>
        <mesh name="pelvis" file="pelvis.STL" />
        <mesh name="left_hip_pitch_link" file="left_hip_pitch_link.STL" />
        <mesh name="left_hip_roll_link" file="left_hip_roll_link.STL" />
        <mesh name="left_hip_yaw_link" file="left_hip_yaw_link.STL" />
        <mesh name="left_knee_link" file="left_knee_link.STL" />
        <mesh name="left_ankle_pitch_link" file="left_ankle_pitch_link.STL" />
        <mesh name="left_ankle_roll_link" file="left_ankle_roll_link.STL" />
        <mesh name="right_hip_pitch_link" file="right_hip_pitch_link.STL" />
        <mesh name="right_hip_roll_link" file="right_hip_roll_link.STL" />
        <mesh name="right_hip_yaw_link" file="right_hip_yaw_link.STL" />
        <mesh name="right_knee_link" file="right_knee_link.STL" />
        <mesh name="right_ankle_pitch_link" file="right_ankle_pitch_link.STL" />
        <mesh name="right_ankle_roll_link" file="right_ankle_roll_link.STL" />
        <mesh name="waist_yaw_link" file="waist_yaw_link.STL" />
        <mesh name="torso_link" file="torso_link.STL" />
        <mesh name="left_shoulder_pitch_link" file="left_shoulder_pitch_link.STL" />
        <mesh name="left_shoulder_roll_link" file="left_shoulder_roll_link.STL" />
        <mesh name="left_shoulder_yaw_link" file="left_shoulder_yaw_link.STL" />
        <mesh name="left_elbow_link" file="left_elbow_link.STL" />
        <mesh name="left_wrist_yaw_link" file="left_wrist_yaw_link.STL" />
        <mesh name="right_shoulder_pitch_link" file="right_shoulder_pitch_link.STL" />
        <mesh name="right_shoulder_roll_link" file="right_shoulder_roll_link.STL" />
        <mesh name="right_shoulder_yaw_link" file="right_shoulder_yaw_link.STL" />
        <mesh name="right_elbow_link" file="right_elbow_link.STL" />
        <mesh name="right_wrist_yaw_link" file="right_wrist_yaw_link.STL" />
    </asset>
    <worldbody>
        <body name="pelvis" pos="0 0 0.70">
            <inertial pos="-3.3339e-05 -1.0813e-06 0.091155" quat="1 1.72829e-05 -0.000408766 -3.74865e-05" mass="2.8438" diaginertia="0.0104787 0.00941324 0.00564707" />
            <joint name="base_footprint_joint" type="free" />
            <geom type="mesh" contype="0" conaffinity="0" group="1" rgba="0.75294 1 1 1" mesh="pelvis" />
            <geom type="mesh" rgba="0.75294 1 1 1" mesh="pelvis" />
            <site name='imu' size='0.01' pos='0.0 0 0.0' />
            <body name="left_hip_pitch_link" pos="0 0.056 0.0605">
                <inertial pos="0.0026859 0.030181 -0.038307" quat="0.718688 0.000735884 -0.122441 0.684467" mass="0.47307" diaginertia="0.00113345 0.000935854 0.000446312" />
                <joint name="left_hip_pitch_joint" pos="0 0 0" axis="0 1 0" limited="true" range="-2.5 2.5" />
                <geom type="mesh" contype="0" conaffinity="0" group="1" rgba="0.75294 1 1 1" mesh="left_hip_pitch_link" />
                <geom type="mesh" rgba="0.75294 1 1 1" mesh="left_hip_pitch_link" />
                <body name="left_hip_roll_link" pos="0 0.0365 -0.092">
                    <inertial pos="0.00077985 -7.5152e-06 -0.043617" quat="0.999954 -2.45618e-05 -0.00958166 -0.000375054" mass="1.7024" diaginertia="0.00593347 0.00560799 0.00196091" />
                    <joint name="left_hip_roll_joint" pos="0 0 0" axis="1 0 0" limited="true" range="-0.5 2.5" />
                    <geom type="mesh" contype="0" conaffinity="0" group="1" rgba="0.69804 0.69804 0.69804 1" mesh="left_hip_roll_link" />
                    <geom type="mesh" rgba="0.69804 0.69804 0.69804 1" mesh="left_hip_roll_link" />
                    <body name="left_hip_yaw_link" pos="0.00175 0 -0.1245">
                        <inertial pos="0 -0.0001553 -0.137967" quat="0.707091 0.00306059 -0.0030642 0.70711" mass="2.07306" diaginertia="0.00728098 0.00653494 0.00248612" />
                        <joint name="left_hip_yaw_joint" pos="0 0 0" axis="0 0 1" limited="true" range="-2.5 2.5" />
                        <geom type="mesh" contype="0" conaffinity="0" group="1" rgba="0.75294 1 1 1" mesh="left_hip_yaw_link" />
                        <geom type="mesh" rgba="0.75294 1 1 1" mesh="left_hip_yaw_link" />
                        <body name="left_knee_link" pos="0 0 -0.1605">
                            <inertial pos="-0.00490708 0.00049315 -0.15002" quat="0.869583 -0.00783506 0.0382035 0.492244" mass="1.48183" diaginertia="0.00537323 0.00526246 0.00159807" />
                            <joint name="left_knee_joint" pos="0 0 0" axis="0 1 0" limited="true" range="-2.5 2.5" />
                            <geom type="mesh" contype="0" conaffinity="0" group="1" rgba="0.69804 0.69804 0.69804 1" mesh="left_knee_link" />
                            <geom type="mesh" rgba="0.69804 0.69804 0.69804 1" mesh="left_knee_link" />
                            <body name="left_ankle_pitch_link" pos="-4.3311e-05 0 -0.257" quat="1 0 8.4265e-05 0">
                                <inertial pos="-1.1905e-08 -3.0215e-11 -7.7016e-10" quat="0.5 0.5 -0.5 0.5" mass="0.023877" diaginertia="9.58e-06 9.56e-06 6.2e-07" />
                                <joint name="left_ankle_pitch_joint" pos="0 0 0" axis="0 1 0" limited="true" range="-0.55 0.55" />
                                <geom type="mesh" contype="0" conaffinity="0" group="1" rgba="0.75294 1 1 1" mesh="left_ankle_pitch_link" />
                                <body name="left_ankle_roll_link" pos="0 0 0">
                                    <inertial pos="0.016184 -9.3563e-10 -0.033038" quat="0 0.723964 0 0.689838" mass="1.1614" diaginertia="0.00584278 0.0053827 0.000891504" />
                                    <joint name="left_ankle_roll_joint" pos="0 0 0" axis="1 0 0" limited="true" range="-0.25 0.25" />
                                    <geom type="mesh" contype="0" conaffinity="0" group="1" rgba="0.75294 1 1 1" mesh="left_ankle_roll_link" />
                                    <geom size="0.005" pos="-0.05 0.05 -0.04" rgba="0.75294 1 1 1" />
                                    <geom size="0.005" pos="-0.05 -0.05 -0.04" rgba="0.75294 1 1 1" />
                                    <geom size="0.005" pos="0.12 0.055 -0.04" rgba="0.75294 1 1 1" />
                                    <geom size="0.005" pos="0.12 -0.055 -0.04" rgba="0.75294 1 1 1" />
                                    <geom size="0.005" pos="0.05 -0.06 -0.04" rgba="0.75294 1 1 1" />
                                    <geom size="0.005" pos="0.05 0.06 -0.04" rgba="0.75294 1 1 1" />
                                    <geom size="0.005" pos="0.14 0 -0.04" rgba="0.75294 1 1 1" />
                                    <geom size="0.005" pos="-0.11 0 -0.04" rgba="0.75294 1 1 1" />
                                    <geom size="0.005" pos="0.1 0 -0.02" rgba="0.75294 1 1 1" />
                                    <geom size="0.005" pos="0.165 0 -0.04" rgba="0.75294 1 1 1" />
                                </body>
                            </body>
                        </body>
                    </body>
                </body>
            </body>
            <body name="right_hip_pitch_link" pos="0 -0.056 0.0605">
                <inertial pos="0.0026859 -0.030181 -0.038307" quat="0.684467 -0.122441 0.000735884 0.718688" mass="0.47307" diaginertia="0.00113345 0.000935854 0.000446312" />
                <joint name="right_hip_pitch_joint" pos="0 0 0" axis="0 1 0" limited="true" range="-2.5 2.5" />
                <geom type="mesh" contype="0" conaffinity="0" group="1" rgba="0.75294 1 1 1" mesh="right_hip_pitch_link" />
                <geom type="mesh" rgba="0.75294 1 1 1" mesh="right_hip_pitch_link" />
                <body name="right_hip_roll_link" pos="0 -0.0365 -0.092">
                    <inertial pos="0.00077985 -7.5152e-06 -0.043617" quat="0.999954 -2.45618e-05 -0.00958166 -0.000375054" mass="1.7024" diaginertia="0.00593347 0.00560799 0.00196091" />
                    <joint name="right_hip_roll_joint" pos="0 0 0" axis="1 0 0" limited="true" range="-2.5 0.5" />
                    <geom type="mesh" contype="0" conaffinity="0" group="1" rgba="0.75294 1 1 1" mesh="right_hip_roll_link" />
                    <geom type="mesh" rgba="0.75294 1 1 1" mesh="right_hip_roll_link" />
                    <body name="right_hip_yaw_link" pos="0.00175 0 -0.1245">
                        <inertial pos="0 0.0001553 -0.137967" quat="0.707091 -0.00306059 0.0030642 0.70711" mass="2.07306" diaginertia="0.00728098 0.00653494 0.00248612" />
                        <joint name="right_hip_yaw_joint" pos="0 0 0" axis="0 0 1" limited="true" range="-2.5 2.5" />
                        <geom type="mesh" contype="0" conaffinity="0" group="1" rgba="0.75294 1 1 1" mesh="right_hip_yaw_link" />
                        <geom type="mesh" rgba="0.75294 1 1 1" mesh="right_hip_yaw_link" />
                        <body name="right_knee_link" pos="0 0 -0.1605">
                            <inertial pos="-0.00490708 -0.00049315 -0.150016" quat="0.492133 0.0381677 -0.00785858 0.869647" mass="1.48183" diaginertia="0.00537323 0.00526236 0.00159809" />
                            <joint name="right_knee_joint" pos="0 0 0" axis="0 1 0" limited="true" range="-2.5 2.5" />
                            <geom type="mesh" contype="0" conaffinity="0" group="1" rgba="0.69804 0.69804 0.69804 1" mesh="right_knee_link" />
                            <geom type="mesh" rgba="0.69804 0.69804 0.69804 1" mesh="right_knee_link" />
                            <body name="right_ankle_pitch_link" pos="-4.3311e-05 0 -0.257" quat="1 0 8.4265e-05 0">
                                <inertial pos="-1.1905e-08 -3.0218e-11 -7.7016e-10" quat="0.5 0.5 -0.5 0.5" mass="0.023877" diaginertia="9.58e-06 9.56e-06 6.2e-07" />
                                <joint name="right_ankle_pitch_joint" pos="0 0 0" axis="0 1 0" limited="true" range="-0.55 0.55" />
                                <geom type="mesh" contype="0" conaffinity="0" group="1" rgba="0.75294 1 1 1" mesh="right_ankle_pitch_link" />
                                <body name="right_ankle_roll_link" pos="0 0 0">
                                    <inertial pos="0.016184 -9.3564e-10 -0.033038" quat="0 0.723964 0 0.689838" mass="1.1614" diaginertia="0.00584278 0.0053827 0.000891504" />
                                    <joint name="right_ankle_roll_joint" pos="0 0 0" axis="1 0 0" limited="true" range="-0.25 0.25" />
                                    <geom type="mesh" contype="0" conaffinity="0" group="1" rgba="0.75294 1 1 1" mesh="right_ankle_roll_link" />
                                    <geom size="0.005" pos="-0.05 0.05 -0.04" rgba="0.75294 1 1 1" />
                                    <geom size="0.005" pos="-0.05 -0.05 -0.04" rgba="0.75294 1 1 1" />
                                    <geom size="0.005" pos="0.12 0.055 -0.04" rgba="0.75294 1 1 1" />
                                    <geom size="0.005" pos="0.12 -0.055 -0.04" rgba="0.75294 1 1 1" />
                                    <geom size="0.005" pos="0.05 -0.06 -0.04" rgba="0.75294 1 1 1" />
                                    <geom size="0.005" pos="0.05 0.06 -0.04" rgba="0.75294 1 1 1" />
                                    <geom size="0.005" pos="0.14 0 -0.04" rgba="0.75294 1 1 1" />
                                    <geom size="0.005" pos="-0.11 0 -0.04" rgba="0.75294 1 1 1" />
                                    <geom size="0.005" pos="0.1 0 -0.02" rgba="0.75294 1 1 1" />
                                    <geom size="0.005" pos="0.165 0 -0.04" rgba="0.75294 1 1 1" />
                                </body>
                            </body>
                        </body>
                    </body>
                </body>
            </body>
            <body name="waist_yaw_link" pos="0 0 0.177">
                <inertial pos="-8.6742e-09 -0.0035731 0.038467" quat="0.891406 0.453206 0 0" mass="0.33855" diaginertia="0.00059365 0.000454518 0.000343252" />
                <joint name="waist_yaw_joint" pos="0 0 0" axis="0 0 1" limited="true" range="-2.5 2.5" />
                <geom type="mesh" contype="0" conaffinity="0" group="1" rgba="0.75294 1 1 1" mesh="waist_yaw_link" />
                <geom type="mesh" rgba="0.75294 1 1 1" mesh="waist_yaw_link" />
                <body name="torso_link" pos="0 0 0.069">
                    <inertial pos="-0.0028374 1.8764e-05 0.11742" quat="0.999727 -0.00422614 0.0222227 0.00587371" mass="8.4343" diaginertia="0.0539086 0.0482918 0.0321743" />
<!--                    <joint name="waist_pitch_joint" pos="0 0 0" axis="0 1 0" limited="true" range="-1.57 1.57" />-->
                    <geom type="mesh" contype="0" conaffinity="0" group="1" rgba="0.69804 0.69804 0.69804 1" mesh="torso_link" />
                    <geom type="mesh" rgba="0.69804 0.69804 0.69804 1" mesh="torso_link" />
                    <body name="left_shoulder_pitch_link" pos="0 0.12875 0.1945">
                        <inertial pos="0.021414 0.043756 -7.7846e-11" quat="0.693283 0.693283 -0.139134 -0.139134" mass="0.48864" diaginertia="0.000175358 0.00014485 7.91117e-05" />
                        <joint name="left_shoulder_pitch_joint" pos="0 0 0" axis="0 1 0" limited="true" range="-3 3" />
                        <geom type="mesh" contype="0" conaffinity="0" group="1" rgba="0.75294 1 1 1" mesh="left_shoulder_pitch_link" />
                        <geom type="mesh" rgba="0.75294 1 1 1" mesh="left_shoulder_pitch_link" />
                        <body name="left_shoulder_roll_link" pos="0 0.047 0">
                            <inertial pos="0 0.0016422 -0.019214" quat="0.541537 0.454684 0.541537 0.454684" mass="0.053968" diaginertia="4.6587e-05 4.0909e-05 1.8069e-05" />
                            <joint name="left_shoulder_roll_joint" pos="0 0 0" axis="1 0 0" limited="true" range="-0.1 3.14" />
                            <geom type="mesh" contype="0" conaffinity="0" group="1" rgba="0.75294 1 1 1" mesh="left_shoulder_roll_link" />
                            <geom type="mesh" rgba="0.75294 1 1 1" mesh="left_shoulder_roll_link" />
                            <body name="left_shoulder_yaw_link" pos="0 0.007 -0.033">
                                <inertial pos="2.3458e-05 0.010492 -0.079775" quat="0.70307 0.0886776 -0.0880535 0.700054" mass="0.99729" diaginertia="0.00223302 0.00221488 0.000287941" />
                                <joint name="left_shoulder_yaw_joint" pos="0 0 0" axis="0 0 1" limited="true" range="-3 3" />
                                <geom type="mesh" contype="0" conaffinity="0" group="1" rgba="0.8549 0.80392 0.52941 1" mesh="left_shoulder_yaw_link" />
                                <geom type="mesh" rgba="0.8549 0.80392 0.52941 1" mesh="left_shoulder_yaw_link" />
                                <body name="left_elbow_link" pos="0 0 -0.1244">
                                    <inertial pos="0 0 -0.02168" quat="0.707107 0.707107 0 0" mass="0.047607" diaginertia="3.565e-05 3.3394e-05 1.1477e-05" />
                                    <joint name="left_elbow_joint" pos="0 0 0" axis="0 1 0" limited="true" range="-2 2" />
                                    <geom type="mesh" contype="0" conaffinity="0" group="1" rgba="0.75294 1 1 1" mesh="left_elbow_link" />
                                    <geom type="mesh" rgba="0.75294 1 1 1" mesh="left_elbow_link" />
                                    <body name="left_wrist_yaw_link" pos="0 0 -0.034">
                                        <inertial pos="-1.211e-08 0.0015412 -0.095114" quat="0.999999 0.00142121 -0.000270251 0.000229832" mass="0.74918" diaginertia="0.00235166 0.00234444 0.000184392" />
                                        <joint name="left_wrist_yaw_joint" pos="0 0 0" axis="0 0 1" limited="true" range="-3 3" />
                                        <geom type="mesh" contype="0" conaffinity="0" group="1" rgba="0.69804 0.69804 0.69804 1" mesh="left_wrist_yaw_link" />
                                        <geom type="mesh" rgba="0.69804 0.69804 0.69804 1" mesh="left_wrist_yaw_link" />
                                    </body>
                                </body>
                            </body>
                        </body>
                    </body>
                    <body name="right_shoulder_pitch_link" pos="0 -0.12875 0.1945">
                        <inertial pos="-0.021414 -0.043756 -7.7846e-11" quat="0.693283 0.693283 -0.139134 -0.139134" mass="0.48864" diaginertia="0.000175358 0.00014485 7.91117e-05" />
                        <joint name="right_shoulder_pitch_joint" pos="0 0 0" axis="0 1 0" limited="true" range="-3 3" />
                        <geom type="mesh" contype="0" conaffinity="0" group="1" rgba="0.75294 1 1 1" mesh="right_shoulder_pitch_link" />
                        <geom type="mesh" rgba="0.75294 1 1 1" mesh="right_shoulder_pitch_link" />
                        <body name="right_shoulder_roll_link" pos="0 -0.047 0">
                            <inertial pos="0 -0.0016422 -0.019214" quat="0.454684 0.541537 0.454684 0.541537" mass="0.053968" diaginertia="4.6587e-05 4.0909e-05 1.8069e-05" />
                            <joint name="right_shoulder_roll_joint" pos="0 0 0" axis="1 0 0" limited="true" range="-3.14 0.1" />
                            <geom type="mesh" contype="0" conaffinity="0" group="1" rgba="0.75294 1 1 1" mesh="right_shoulder_roll_link" />
                            <geom type="mesh" rgba="0.75294 1 1 1" mesh="right_shoulder_roll_link" />
                            <body name="right_shoulder_yaw_link" pos="0 -0.007 -0.033">
                                <inertial pos="-2.3457e-05 0.010492 -0.079775" quat="0.699866 0.0880294 -0.0887015 0.703257" mass="0.99729" diaginertia="0.00223302 0.00221488 0.000287941" />
                                <joint name="right_shoulder_yaw_joint" pos="0 0 0" axis="0 0 1" limited="true" range="-3 3" />
                                <geom type="mesh" contype="0" conaffinity="0" group="1" rgba="0.8549 0.80392 0.52941 1" mesh="right_shoulder_yaw_link" />
                                <geom type="mesh" rgba="0.8549 0.80392 0.52941 1" mesh="right_shoulder_yaw_link" />
                                <body name="right_elbow_link" pos="0 0 -0.1244">
                                    <inertial pos="0 0 -0.02168" quat="0.707107 0.707107 0 0" mass="0.047607" diaginertia="3.565e-05 3.3394e-05 1.1477e-05" />
                                    <joint name="right_elbow_joint" pos="0 0 0" axis="0 1 0" limited="true" range="-2 2" />
                                    <geom type="mesh" contype="0" conaffinity="0" group="1" rgba="0.75294 1 1 1" mesh="right_elbow_link" />
                                    <geom type="mesh" rgba="0.75294 1 1 1" mesh="right_elbow_link" />
                                    <body name="right_wrist_yaw_link" pos="0 0 -0.034">
                                        <inertial pos="-1.211e-08 0.0015412 -0.095114" quat="0.999999 0.00142121 -0.000270251 0.000229832" mass="0.74918" diaginertia="0.00235166 0.00234444 0.000184392" />
                                        <joint name="right_wrist_yaw_joint" pos="0 0 0" axis="0 0 1" limited="true" range="-3 3" />
                                        <geom type="mesh" contype="0" conaffinity="0" group="1" rgba="0.69804 0.69804 0.69804 1" mesh="right_wrist_yaw_link" />
                                        <geom type="mesh" rgba="0.69804 0.69804 0.69804 1" mesh="right_wrist_yaw_link" />
                                    </body>
                                </body>
                            </body>
                        </body>
                    </body>
                </body>
            </body>
        </body>
    </worldbody>
    <actuator>
        <motor name="left_hip_pitch_joint" joint="left_hip_pitch_joint" gear="1" ctrllimited="true" ctrlrange="-500 500" />
        <motor name="left_hip_roll_joint" joint="left_hip_roll_joint" gear="1" ctrllimited="true" ctrlrange="-500 500"/>
        <motor name="left_hip_yaw_joint" joint="left_hip_yaw_joint" gear="1" ctrllimited="true" ctrlrange="-500 500"/>
        <motor name="left_knee_joint" joint="left_knee_joint" gear="1" ctrllimited="true" ctrlrange="-500 500"/>
        <motor name="left_ankle_pitch_joint" joint="left_ankle_pitch_joint" gear="1" ctrllimited="true" ctrlrange="-500 500"/>
        <motor name="left_ankle_roll_joint" joint="left_ankle_roll_joint" gear="1" ctrllimited="true" ctrlrange="-500 500"/>
        <motor name="right_hip_pitch_joint" joint="right_hip_pitch_joint" gear="1" ctrllimited="true" ctrlrange="-500 500"/>
        <motor name="right_hip_roll_joint" joint="right_hip_roll_joint" gear="1" ctrllimited="true" ctrlrange="-500 500"/>
        <motor name="right_hip_yaw_joint" joint="right_hip_yaw_joint" gear="1" ctrllimited="true" ctrlrange="-500 500"/>
        <motor name="right_knee_joint" joint="right_knee_joint" gear="1" ctrllimited="true" ctrlrange="-500 500"/>
        <motor name="right_ankle_pitch_joint" joint="right_ankle_pitch_joint" gear="1" ctrllimited="true" ctrlrange="-500 500"/>
        <motor name="right_ankle_roll_joint" joint="right_ankle_roll_joint" gear="1" ctrllimited="true" ctrlrange="-500 500"/>
        <motor name="waist_yaw_joint" joint="waist_yaw_joint" gear="1" ctrllimited="true" ctrlrange="-500 500"/>
        <motor name="left_shoulder_pitch_joint" joint="left_shoulder_pitch_joint" gear="1" ctrllimited="true" ctrlrange="-500 500"/>
        <motor name="left_shoulder_roll_joint" joint="left_shoulder_roll_joint" gear="1" ctrllimited="true" ctrlrange="-500 500"/>
        <motor name="left_shoulder_yaw_joint" joint="left_shoulder_yaw_joint" gear="1" ctrllimited="true" ctrlrange="-500 500"/>
        <motor name="left_elbow_joint" joint="left_elbow_joint" gear="1" ctrllimited="true" ctrlrange="-500 500"/>
        <motor name="left_wrist_yaw_joint" joint="left_wrist_yaw_joint" gear="1" ctrllimited="true" ctrlrange="-500 500"/>
        <motor name="right_shoulder_pitch_joint" joint="right_shoulder_pitch_joint" gear="1" ctrllimited="true" ctrlrange="-500 500"/>
        <motor name="right_shoulder_roll_joint" joint="right_shoulder_roll_joint" gear="1" ctrllimited="true" ctrlrange="-500 500"/>
        <motor name="right_shoulder_yaw_joint" joint="right_shoulder_yaw_joint" gear="1" ctrllimited="true" ctrlrange="-500 500"/>
        <motor name="right_elbow_joint" joint="right_elbow_joint" gear="1" ctrllimited="true" ctrlrange="-500 500"/>
        <motor name="right_wrist_yaw_joint" joint="right_wrist_yaw_joint" gear="1" ctrllimited="true" ctrlrange="-500 500"/>
    </actuator>
    <sensor>
            <actuatorpos name='left_hip_pitch_joint_p'  actuator='left_hip_pitch_joint' user='13'/>
            <actuatorpos name='left_hip_roll_joint_p'  actuator='left_hip_roll_joint' user='13'/>
            <actuatorpos name='left_hip_yaw_joint_p'  actuator='left_hip_yaw_joint' user='13'/>
            <actuatorpos name='left_knee_joint_p'  actuator='left_knee_joint' user='13'/>
            <actuatorpos name='left_ankle_pitch_joint_p'  actuator='left_ankle_pitch_joint' user='13'/>
            <actuatorpos name='left_ankle_roll_joint_p'  actuator='left_ankle_roll_joint' user='13'/>
            <actuatorpos name='right_hip_pitch_joint_p'  actuator='right_hip_pitch_joint' user='13'/>
            <actuatorpos name='right_hip_roll_joint_p'  actuator='right_hip_roll_joint' user='13'/>
            <actuatorpos name='right_hip_yaw_joint_p'  actuator='right_hip_yaw_joint' user='13'/>
            <actuatorpos name='right_knee_joint_p'  actuator='right_knee_joint' user='13'/>
            <actuatorpos name='right_ankle_pitch_joint_p'  actuator='right_ankle_pitch_joint' user='13'/>
            <actuatorpos name='right_ankle_roll_joint_p'  actuator='right_ankle_roll_joint' user='13'/>
            <actuatorpos name='waist_yaw_joint_p'  actuator='waist_yaw_joint' user='13'/>
            <actuatorpos name='left_shoulder_pitch_joint_p'  actuator='left_shoulder_pitch_joint' user='13'/>
            <actuatorpos name='left_shoulder_roll_joint_p'  actuator='left_shoulder_roll_joint' user='13'/>
            <actuatorpos name='left_shoulder_yaw_joint_p'  actuator='left_shoulder_yaw_joint' user='13'/>
            <actuatorpos name='left_elbow_joint_p'  actuator='left_elbow_joint' user='13'/>
            <actuatorpos name='left_wrist_yaw_joint_p'  actuator='left_wrist_yaw_joint' user='13'/>
            <actuatorpos name='right_shoulder_pitch_joint_p'  actuator='right_shoulder_pitch_joint' user='13'/>
            <actuatorpos name='right_shoulder_roll_joint_p'  actuator='right_shoulder_roll_joint' user='13'/>
            <actuatorpos name='right_shoulder_yaw_joint_p'  actuator='right_shoulder_yaw_joint' user='13'/>
            <actuatorpos name='right_elbow_joint_p'  actuator='right_elbow_joint' user='13'/>
            <actuatorpos name='right_wrist_yaw_joint_p'  actuator='right_wrist_yaw_joint' user='13'/>

            <actuatorvel name='left_hip_pitch_joint_v'  actuator='left_hip_pitch_joint' user='13'/>
            <actuatorvel name='left_hip_roll_joint_v'  actuator='left_hip_roll_joint' user='13'/>
            <actuatorvel name='left_hip_yaw_joint_v'  actuator='left_hip_yaw_joint' user='13'/>
            <actuatorvel name='left_knee_joint_v'  actuator='left_knee_joint' user='13'/>
            <actuatorvel name='left_ankle_pitch_joint_v'  actuator='left_ankle_pitch_joint' user='13'/>
            <actuatorvel name='left_ankle_roll_joint_v'  actuator='left_ankle_roll_joint' user='13'/>
            <actuatorvel name='right_hip_pitch_joint_v'  actuator='right_hip_pitch_joint' user='13'/>
            <actuatorvel name='right_hip_roll_joint_v'  actuator='right_hip_roll_joint' user='13'/>
            <actuatorvel name='right_hip_yaw_joint_v'  actuator='right_hip_yaw_joint' user='13'/>
            <actuatorvel name='right_knee_joint_v'  actuator='right_knee_joint' user='13'/>
            <actuatorvel name='right_ankle_pitch_joint_v'  actuator='right_ankle_pitch_joint' user='13'/>
            <actuatorvel name='right_ankle_roll_joint_v'  actuator='right_ankle_roll_joint' user='13'/>
            <actuatorpos name='waist_yaw_joint_v'  actuator='waist_yaw_joint' user='13'/>
            <actuatorpos name='left_shoulder_pitch_joint_v'  actuator='left_shoulder_pitch_joint' user='13'/>
            <actuatorpos name='left_shoulder_roll_joint_v'  actuator='left_shoulder_roll_joint' user='13'/>
            <actuatorpos name='left_shoulder_yaw_joint_v'  actuator='left_shoulder_yaw_joint' user='13'/>
            <actuatorpos name='left_elbow_joint_v'  actuator='left_elbow_joint' user='13'/>
            <actuatorpos name='left_wrist_yaw_joint_v'  actuator='left_wrist_yaw_joint' user='13'/>
            <actuatorpos name='right_shoulder_pitch_joint_v'  actuator='right_shoulder_pitch_joint' user='13'/>
            <actuatorpos name='right_shoulder_roll_joint_v'  actuator='right_shoulder_roll_joint' user='13'/>
            <actuatorpos name='right_shoulder_yaw_joint_v'  actuator='right_shoulder_yaw_joint' user='13'/>
            <actuatorpos name='right_elbow_joint_v'  actuator='right_elbow_joint' user='13'/>
            <actuatorpos name='right_wrist_yaw_joint_v'  actuator='right_wrist_yaw_joint' user='13'/>


            <actuatorfrc name='left_hip_pitch_joint_f'  actuator='left_hip_pitch_joint' user='13' noise='1e-3'/>
            <actuatorfrc name='left_hip_roll_joint_f'  actuator='left_hip_roll_joint' user='13' noise='1e-3'/>
            <actuatorfrc name='left_hip_yaw_joint_f'  actuator='left_hip_yaw_joint' user='13' noise='1e-3'/>
            <actuatorfrc name='left_knee_joint_f'  actuator='left_knee_joint' user='13' noise='1e-3'/>
            <actuatorfrc name='left_ankle_pitch_joint_f'  actuator='left_ankle_pitch_joint' user='13' noise='1e-3'/>
            <actuatorfrc name='left_ankle_roll_joint_f'  actuator='left_ankle_roll_joint' user='13' noise='1e-3'/>
            <actuatorfrc name='right_hip_pitch_joint_f'  actuator='right_hip_pitch_joint' user='13' noise='1e-3'/>
            <actuatorfrc name='right_hip_roll_joint_f'  actuator='right_hip_roll_joint' user='13' noise='1e-3'/>
            <actuatorfrc name='right_hip_yaw_joint_f'  actuator='right_hip_yaw_joint' user='13' noise='1e-3'/>
            <actuatorfrc name='right_knee_joint_f'  actuator='right_knee_joint' user='13' noise='1e-3'/>
            <actuatorfrc name='right_ankle_pitch_joint_f'  actuator='right_ankle_pitch_joint' user='13' noise='1e-3'/>
            <actuatorfrc name='right_ankle_roll_joint_f'  actuator='right_ankle_roll_joint' user='13' noise='1e-3'/>
            <actuatorpos name='waist_yaw_joint_f'  actuator='waist_yaw_joint' user='13'/>
            <actuatorpos name='left_shoulder_pitch_joint_f'  actuator='left_shoulder_pitch_joint' user='13'/>
            <actuatorpos name='left_shoulder_roll_joint_f'  actuator='left_shoulder_roll_joint' user='13'/>
            <actuatorpos name='left_shoulder_yaw_joint_f'  actuator='left_shoulder_yaw_joint' user='13'/>
            <actuatorpos name='left_elbow_joint_f'  actuator='left_elbow_joint' user='13'/>
            <actuatorpos name='left_wrist_yaw_joint_f'  actuator='left_wrist_yaw_joint' user='13'/>
            <actuatorpos name='right_shoulder_pitch_joint_f'  actuator='right_shoulder_pitch_joint' user='13'/>
            <actuatorpos name='right_shoulder_roll_joint_f'  actuator='right_shoulder_roll_joint' user='13'/>
            <actuatorpos name='right_shoulder_yaw_joint_f'  actuator='right_shoulder_yaw_joint' user='13'/>
            <actuatorpos name='right_elbow_joint_f'  actuator='right_elbow_joint' user='13'/>
            <actuatorpos name='right_wrist_yaw_joint_f'  actuator='right_wrist_yaw_joint' user='13'/>

            <framequat     name='orientation' objtype='site' noise='0.001' objname='imu'/>
            <framepos     name='position' objtype='site' noise='0.001' objname='imu'/>
            <gyro          name='angular-velocity'    site='imu' noise='0.005' cutoff='34.9'/>
            <velocimeter   name='linear-velocity'     site='imu' noise='0.001' cutoff='30'/>
            <accelerometer name='linear-acceleration' site='imu' noise='0.005' cutoff='157'/>
            <magnetometer  name='magnetometer'        site='imu'/>
        </sensor>

  <!-- setup scene -->
  <statistic center="1.0 0.7 1.0" extent="0.8"/>
  <visual>
    <headlight diffuse="0.6 0.6 0.6" ambient="0.1 0.1 0.1" specular="0.9 0.9 0.9"/>
    <rgba haze="0.15 0.25 0.35 1"/>
    <global azimuth="-140" elevation="-20"/>
  </visual>
  <asset>
    <texture type="skybox" builtin="flat" rgb1="0 0 0" rgb2="0 0 0" width="512" height="3072"/>
    <texture type="2d" name="groundplane" builtin="checker" mark="edge" rgb1="0.2 0.3 0.4" rgb2="0.1 0.2 0.3" markrgb="0.8 0.8 0.8" width="300" height="300"/>
    <material name="groundplane" texture="groundplane" texuniform="true" texrepeat="5 5" reflectance="0.2"/>
  </asset>
  <worldbody>
    <light pos="1 0 3.5" dir="0 0 -1" directional="true"/>
    <geom name="floor" size="0 0 0.05" type="plane" material="groundplane" conaffinity="2"/>
  </worldbody>
</mujoco>
