<mujoco model="ymboy-X-22dof">
  <compiler angle="radian" meshdir="../urdf/meshes/"/>

  <asset>
    <mesh name="base_link" file="base_link.STL"/>
    <mesh name="left_hip_pitch_link" file="left_hip_pitch_link.STL"/>
    <mesh name="left_hip_roll_link" file="left_hip_roll_link.STL"/>
    <mesh name="left_hip_yaw_link" file="left_hip_yaw_link.STL"/>
    <mesh name="left_knee_link" file="left_knee_link.STL"/>
    <mesh name="left_ankle_pitch_link" file="left_ankle_pitch_link.STL"/>
    <mesh name="left_ankle_roll_link" file="left_ankle_roll_link.STL"/>
    <mesh name="right_hip_pitch_link" file="right_hip_pitch_link.STL"/>
    <mesh name="right_hip_roll_link" file="right_hip_roll_link.STL"/>
    <mesh name="right_hip_yaw_link" file="right_hip_yaw_link.STL"/>
    <mesh name="right_knee_link" file="right_knee_link.STL"/>
    <mesh name="right_ankle_pitch_link" file="right_ankle_pitch_link.STL"/>
    <mesh name="right_ankle_roll_link" file="right_ankle_roll_link.STL"/>
    <mesh name="waist_yaw_link" file="waist_yaw_link.STL"/>
    <mesh name="torso_link" file="torso_link.STL"/>
    <mesh name="left_shoulder_pitch_link" file="left_shoulder_pitch_link.STL"/>
    <mesh name="left_shoulder_roll_link" file="left_shoulder_roll_link.STL"/>
    <mesh name="left_shoulder_yaw_link" file="left_shoulder_yaw_link.STL"/>
    <mesh name="left_elbow_link" file="left_elbow_link.STL"/>
    <mesh name="left_wrist_yaw_link" file="left_wrist_yaw_link.STL"/>
    <mesh name="right_shoulder_pitch_link" file="right_shoulder_pitch_link.STL"/>
    <mesh name="right_shoulder_roll_link" file="right_shoulder_roll_link.STL"/>
    <mesh name="right_shoulder_yaw_link" file="right_shoulder_yaw_link.STL"/>
    <mesh name="right_elbow_link" file="right_elbow_link.STL"/>
    <mesh name="right_wrist_yaw_link" file="right_wrist_yaw_link.STL"/>
    <mesh name="neck_yaw_link" file="neck_yaw_link.STL"/>
    <mesh name="head_link" file="head_link.STL"/>
  </asset>

  <worldbody>
    <body name="base_link">
      <inertial pos="-3.3343e-05 -1.1085e-06 0.091155" quat="1 1.86166e-05 -0.000408767 -4.68679e-05" mass="2.8438" diaginertia="0.0104787 0.00941323 0.00564707"/>
      <joint name="base_footprint_joint" type="free" limited="false" actuatorfrclimited="false"/>
      <geom type="mesh" contype="0" conaffinity="0" group="1" density="0" rgba="0.69804 0.69804 0.69804 1" mesh="base_link"/>
      <body name="left_hip_pitch_link" pos="0 0.056 0.0605">
        <inertial pos="0.0026859 0.030181 -0.038307" quat="0.718688 0.000735884 -0.122441 0.684467" mass="0.47307" diaginertia="0.00113345 0.000935854 0.000446312"/>
        <joint name="left_hip_pitch_joint" pos="0 0 0" axis="0 1 0" range="-1.5 1.5" actuatorfrcrange="-94 94"/>
        <geom type="mesh" contype="0" conaffinity="0" group="1" density="0" rgba="0.75294 1 1 1" mesh="left_hip_pitch_link"/>
        <body name="left_hip_roll_link" pos="0 0.0365 -0.092">
          <inertial pos="0.00077986 -7.5623e-06 -0.043617" quat="0.999954 -2.45618e-05 -0.00958166 -0.000375054" mass="1.7024" diaginertia="0.00593346 0.00560798 0.0019609"/>
          <joint name="left_hip_roll_joint" pos="0 0 0" axis="1 0 0" range="-0.8 0.8" actuatorfrcrange="-94 94"/>
          <geom type="mesh" contype="0" conaffinity="0" group="1" density="0" rgba="0.69804 0.69804 0.69804 1" mesh="left_hip_roll_link"/>
          <body name="left_hip_yaw_link" pos="0.00175 0 -0.1245">
            <inertial pos="1.8297e-09 -0.00090375 -0.083992" quat="0.999997 0.00254203 0 0" mass="0.61054" diaginertia="0.00236125 0.00202276 0.000732437"/>
            <joint name="left_hip_yaw_joint" pos="0 0 0" axis="0 0 1" range="-1.5 1.5" actuatorfrcrange="-60 60"/>
            <geom type="mesh" contype="0" conaffinity="0" group="1" density="0" rgba="0.75294 1 1 1" mesh="left_hip_yaw_link"/>
            <geom size="0.055 0.055 0.1" pos="0 0 0.06" type="box" rgba="0.75294 1 1 1"/>
            <body name="left_knee_link" pos="0 0 -0.1605">
              <inertial pos="-0.0024699 0.00032624 -0.075502" quat="0.720726 0.0104444 0.0161337 0.692953" mass="2.9443" diaginertia="0.0246567 0.0235234 0.00336241"/>
              <joint name="left_knee_joint" pos="0 0 0" axis="0 1 0" range="-0.2 1.5" actuatorfrcrange="-150 150"/>
              <geom type="mesh" contype="0" conaffinity="0" group="1" density="0" rgba="0.69804 0.69804 0.69804 1" mesh="left_knee_link"/>
              <geom size="0.065 0.05 0.1" pos="0 0 -0.08" type="box" rgba="0.69804 0.69804 0.69804 1"/>
              <body name="left_ankle_pitch_link" pos="-4.3311e-05 0 -0.257" quat="1 0 8.4265e-05 0">
                <inertial pos="0 0 0" quat="0.5 0.5 -0.5 0.5" mass="0.023876" diaginertia="9.58e-06 9.56e-06 6.2e-07"/>
                <joint name="left_ankle_pitch_joint" pos="0 0 0" axis="0 1 0" range="-0.55 0.55" actuatorfrcrange="-60 60"/>
                <geom type="mesh" contype="0" conaffinity="0" group="1" density="0" rgba="0.75294 1 1 1" mesh="left_ankle_pitch_link"/>
                <body name="left_ankle_roll_link">
                  <inertial pos="0.014848 -1.4543e-10 -0.032028" quat="0 0.725919 0 0.687781" mass="1.0326" diaginertia="0.00515468 0.00476966 0.000790233"/>
                  <joint name="left_ankle_roll_joint" pos="0 0 0" axis="1 0 0" range="-0.25 0.25" actuatorfrcrange="-60 60"/>
                  <geom type="mesh" contype="0" conaffinity="0" group="1" density="0" rgba="0.75294 1 1 1" mesh="left_ankle_roll_link"/>
                  <geom type="mesh" rgba="0.75294 1 1 1" mesh="left_ankle_roll_link"/>
                </body>
              </body>
            </body>
          </body>
        </body>
      </body>
      <body name="right_hip_pitch_link" pos="0 -0.056 0.0605">
        <inertial pos="0.0026859 -0.030181 -0.038307" quat="0.684467 -0.122441 0.000735884 0.718688" mass="0.47307" diaginertia="0.00113345 0.000935854 0.000446312"/>
        <joint name="right_hip_pitch_joint" pos="0 0 0" axis="0 1 0" range="-1.5 1.5" actuatorfrcrange="-94 94"/>
        <geom type="mesh" contype="0" conaffinity="0" group="1" density="0" rgba="0.75294 1 1 1" mesh="right_hip_pitch_link"/>
        <body name="right_hip_roll_link" pos="0 -0.0365 -0.092">
          <inertial pos="0.00077986 -7.5623e-06 -0.043617" quat="0.999954 -2.45618e-05 -0.00958166 -0.000375054" mass="1.7024" diaginertia="0.00593346 0.00560798 0.0019609"/>
          <joint name="right_hip_roll_joint" pos="0 0 0" axis="1 0 0" range="-0.8 0.8" actuatorfrcrange="-94 94"/>
          <geom type="mesh" contype="0" conaffinity="0" group="1" density="0" rgba="0.69804 0.69804 0.69804 1" mesh="right_hip_roll_link"/>
          <body name="right_hip_yaw_link" pos="0.00175 0 -0.1245">
            <inertial pos="1.6241e-09 0.00090374 -0.083992" quat="0.999997 -0.00254203 0 0" mass="0.61054" diaginertia="0.00236125 0.00202276 0.000732437"/>
            <joint name="right_hip_yaw_joint" pos="0 0 0" axis="0 0 1" range="-1.5 1.5" actuatorfrcrange="-60 60"/>
            <geom type="mesh" contype="0" conaffinity="0" group="1" density="0" rgba="0.75294 1 1 1" mesh="right_hip_yaw_link"/>
            <geom size="0.055 0.055 0.1" pos="0 0 0.06" type="box" rgba="0.75294 1 1 1"/>
            <body name="right_knee_link" pos="0 0 -0.1605">
              <inertial pos="-0.0024694 -0.00032624 -0.0755" quat="0.692915 0.0161325 0.0104418 0.720763" mass="2.9443" diaginertia="0.0246558 0.0235226 0.00336239"/>
              <joint name="right_knee_joint" pos="0 0 0" axis="0 1 0" range="-0.2 1.5" actuatorfrcrange="-150 150"/>
              <geom type="mesh" contype="0" conaffinity="0" group="1" density="0" rgba="0.69804 0.69804 0.69804 1" mesh="right_knee_link"/>
              <geom size="0.065 0.05 0.1" pos="0 0 -0.08" type="box" rgba="0.69804 0.69804 0.69804 1"/>
              <body name="right_ankle_pitch_link" pos="-4.3311e-05 0 -0.257" quat="1 0 8.4265e-05 0">
                <inertial pos="0 0 0" quat="0.5 0.5 -0.5 0.5" mass="0.023876" diaginertia="9.58e-06 9.56e-06 6.2e-07"/>
                <joint name="right_ankle_pitch_joint" pos="0 0 0" axis="0 1 0" range="-0.55 0.55" actuatorfrcrange="-60 60"/>
                <geom type="mesh" contype="0" conaffinity="0" group="1" density="0" rgba="0.75294 1 1 1" mesh="right_ankle_pitch_link"/>
                <body name="right_ankle_roll_link">
                  <inertial pos="0.014848 -1.4543e-10 -0.032028" quat="0 0.725919 0 0.687781" mass="1.0326" diaginertia="0.00515468 0.00476966 0.000790233"/>
                  <joint name="right_ankle_roll_joint" pos="0 0 0" axis="1 0 0" range="-0.25 0.25" actuatorfrcrange="-60 60"/>
                  <geom type="mesh" contype="0" conaffinity="0" group="1" density="0" rgba="0.75294 1 1 1" mesh="right_ankle_roll_link"/>
                  <geom type="mesh" rgba="0.75294 1 1 1" mesh="right_ankle_roll_link"/>
                </body>
              </body>
            </body>
          </body>
        </body>
      </body>
      <body name="waist_yaw_link" pos="0 0 0.177">
        <inertial pos="0 0.0022818 0.032571" quat="0.65062 0.759404 0 0" mass="0.28376" diaginertia="0.00045846 0.000342804 0.000292926"/>
        <joint name="waist_yaw_joint" pos="0 0 0" axis="0 0 1" range="-1.5 1.5" actuatorfrcrange="-94 94"/>
        <geom type="mesh" contype="0" conaffinity="0" group="1" density="0" rgba="0.75294 1 1 1" mesh="waist_yaw_link"/>
        <body name="torso_link" pos="0 0 0.069">
          <inertial pos="-0.00278996 1.98201e-05 0.116381" quat="0.999751 -0.00415083 0.0211786 0.00571741" mass="8.57754" diaginertia="0.0546363 0.0488974 0.0324178"/>
          <joint name="waist_pitch_joint" pos="0 0 0" axis="0 1 0" range="-1.5 1.5" actuatorfrcrange="-94 94"/>
          <geom type="mesh" contype="0" conaffinity="0" group="1" density="0" rgba="0.69804 0.69804 0.69804 1" mesh="torso_link"/>
          <geom size="0.125 0.075 0.125" pos="0 0 0.1" type="box" rgba="0.69804 0.69804 0.69804 1"/>
          <geom pos="0 0 0.2215" type="mesh" contype="0" conaffinity="0" group="1" density="0" rgba="0.75294 1 1 1" mesh="neck_yaw_link"/>
          <geom pos="0 0 0.2605" quat="1 0 0 0" type="mesh" contype="0" conaffinity="0" group="1" density="0" rgba="0.75294 1 1 1" mesh="head_link"/>
          <body name="left_shoulder_pitch_link" pos="0 0.12875 0.1945">
            <inertial pos="0.021414 0.043756 -8.8117e-09" quat="0.693283 0.693283 -0.139134 -0.139134" mass="0.48864" diaginertia="0.000175358 0.00014485 7.91117e-05"/>
            <joint name="left_shoulder_pitch_joint" pos="0 0 0" axis="0 1 0" range="-1.57 1.57" actuatorfrcrange="-12 12"/>
            <geom type="mesh" contype="0" conaffinity="0" group="1" density="0" rgba="0.75294 1 1 1" mesh="left_shoulder_pitch_link"/>
            <body name="left_shoulder_roll_link" pos="0 0.047 0">
              <inertial pos="0 0.0016422 -0.019214" quat="0.4546 0.541608 0.4546 0.541608" mass="0.053968" diaginertia="4.65907e-05 4.09093e-05 1.807e-05"/>
              <joint name="left_shoulder_roll_joint" pos="0 0 0" axis="1 0 0" range="-0.1 3.14" actuatorfrcrange="-12 12"/>
              <geom type="mesh" contype="0" conaffinity="0" group="1" density="0" rgba="0.75294 1 1 1" mesh="left_shoulder_roll_link"/>
              <body name="left_shoulder_yaw_link" pos="0 0.007 -0.033">
                <inertial pos="2.3792e-05 0.010631 -0.080367" quat="0.703152 0.0889075 -0.0882464 0.699918" mass="0.9843" diaginertia="0.00219865 0.00218027 0.000283592"/>
                <joint name="left_shoulder_yaw_joint" pos="0 0 0" axis="0 0 1" range="-1.57 1.57" actuatorfrcrange="-12 12"/>
                <geom type="mesh" contype="0" conaffinity="0" group="1" density="0" rgba="0.69804 0.69804 0.69804 1" mesh="left_shoulder_yaw_link"/>
                <geom type="mesh" rgba="0.69804 0.69804 0.69804 1" mesh="left_shoulder_yaw_link"/>
                <body name="left_elbow_link" pos="0 0 -0.1244" quat="0.731689 0 -0.681639 0">
                  <inertial pos="7.31566e-08 5.37618e-09 -0.0532572" quat="1 9.96743e-11 2.37838e-06 -4.19085e-05" mass="0.241737" diaginertia="0.000159064 0.000135904 7.0933e-05"/>
                  <joint name="left_elbow_joint" pos="0 0 0" axis="0 1 0" range="-1.57 1.57" actuatorfrcrange="-12 12"/>
                  <geom type="mesh" contype="0" conaffinity="0" group="1" density="0" rgba="0.75294 1 1 1" mesh="left_elbow_link"/>
                  <geom pos="0 0 -0.034" type="mesh" contype="0" conaffinity="0" group="1" density="0" rgba="0.69804 0.69804 0.69804 1" mesh="left_wrist_yaw_link"/>
                </body>
              </body>
            </body>
          </body>
          <body name="right_shoulder_pitch_link" pos="0 -0.12875 0.1945">
            <inertial pos="-0.021414 -0.043756 -8.8117e-09" quat="0.693283 0.693283 -0.139134 -0.139134" mass="0.48864" diaginertia="0.000175358 0.00014485 7.91117e-05"/>
            <joint name="right_shoulder_pitch_joint" pos="0 0 0" axis="0 1 0" range="-1.57 1.57" actuatorfrcrange="-12 12"/>
            <geom type="mesh" contype="0" conaffinity="0" group="1" density="0" rgba="0.75294 1 1 1" mesh="right_shoulder_pitch_link"/>
            <body name="right_shoulder_roll_link" pos="0 -0.047 0">
              <inertial pos="0 -0.0016422 -0.019214" quat="0.454684 0.541537 0.454684 0.541537" mass="0.053968" diaginertia="4.6587e-05 4.0909e-05 1.8069e-05"/>
              <joint name="right_shoulder_roll_joint" pos="0 0 0" axis="1 0 0" range="-3.14 0.1" actuatorfrcrange="-12 12"/>
              <geom type="mesh" contype="0" conaffinity="0" group="1" density="0" rgba="0.75294 1 1 1" mesh="right_shoulder_roll_link"/>
              <body name="right_shoulder_yaw_link" pos="0 -0.007 -0.033">
                <inertial pos="-2.3783e-05 0.010631 -0.080367" quat="0.699918 0.0882464 -0.0889075 0.703152" mass="0.9843" diaginertia="0.00219865 0.00218027 0.000283592"/>
                <joint name="right_shoulder_yaw_joint" pos="0 0 0" axis="0 0 1" range="-1.57 1.57" actuatorfrcrange="-12 12"/>
                <geom type="mesh" contype="0" conaffinity="0" group="1" density="0" rgba="0.69804 0.69804 0.69804 1" mesh="right_shoulder_yaw_link"/>
                <geom type="mesh" rgba="0.69804 0.69804 0.69804 1" mesh="right_shoulder_yaw_link"/>
                <body name="right_elbow_link" pos="0 0 -0.1244" quat="0.731689 0 -0.681639 0">
                  <inertial pos="7.31566e-08 5.37618e-09 -0.0532572" quat="1 9.96743e-11 2.37838e-06 -4.19085e-05" mass="0.241737" diaginertia="0.000159064 0.000135904 7.0933e-05"/>
                  <joint name="right_elbow_joint" pos="0 0 0" axis="0 1 0" range="-1.57 1.57" actuatorfrcrange="-12 12"/>
                  <geom type="mesh" contype="0" conaffinity="0" group="1" density="0" rgba="0.75294 1 1 1" mesh="right_elbow_link"/>
                  <geom pos="0 0 -0.034" type="mesh" contype="0" conaffinity="0" group="1" density="0" rgba="0.69804 0.69804 0.69804 1" mesh="right_wrist_yaw_link"/>
                </body>
              </body>
            </body>
          </body>
        </body>
      </body>
    </body>
  </worldbody>
</mujoco>
