<mujoco model="g1_23dof">
  <compiler angle="radian" meshdir="/home/ps/catkin_ws/src/ymbot_amp_devel/robots/unitree_g1/urdf/meshes/" />
  <option timestep='0.002' iterations='50' solver='Newton' gravity='0 0 -9.81' integrator = 'RK4'/>
  <size njmax="500" nconmax="100" />

  <size nuser_actuator='1' nuser_sensor='1' nuser_geom='1'/>

  <visual>
    <quality shadowsize='4096'/>
    <map znear='0.01'/>
    <!-- <camera name="default" mode="trackcom" pos="2.0 2.0 2.0" xyaxes="1 0 0 0 1 0" camdist="3.0" fovy="45" aspect="1.33" />
    <view width="800" height="600" camtype="fixed" viewangle="60" camtrack="default" azimuth="0.5"/> -->
  </visual>

  <default>
    <geom contype='0' conaffinity='0' condim='3' solref='0.01 0.7' rgba="1.0000 0.9804 0.9804 1"/>
  </default>

  <asset>
    <texture name='plane' type='2d' builtin='checker' rgb1='0.2745 0.5098 0.7059' rgb2='0.5294 0.8078 0.9804' width='512' height='512'/>
    <material name='plane' reflectance='0.0' texture='plane' texrepeat='1 1' texuniform='true'/>

    <mesh name="pelvis" file="pelvis.STL"/>
    <mesh name="pelvis_contour_link" file="pelvis_contour_link.STL"/>
    <mesh name="left_hip_pitch_link" file="left_hip_pitch_link.STL"/>
    <mesh name="left_hip_roll_link" file="left_hip_roll_link.STL"/>
    <mesh name="left_hip_yaw_link" file="left_hip_yaw_link.STL"/>
    <mesh name="left_knee_link" file="left_knee_link.STL"/>
    <mesh name="left_ankle_pitch_link" file="left_ankle_pitch_link.STL"/>
    <mesh name="left_ankle_roll_link" file="left_ankle_roll_link.STL"/>
    <mesh name="right_hip_pitch_link" file="right_hip_pitch_link.STL"/>
    <mesh name="right_hip_roll_link" file="right_hip_roll_link.STL"/>
    <mesh name="right_hip_yaw_link" file="right_hip_yaw_link.STL"/>
    <mesh name="right_knee_link" file="right_knee_link.STL"/>
    <mesh name="right_ankle_pitch_link" file="right_ankle_pitch_link.STL"/>
    <mesh name="right_ankle_roll_link" file="right_ankle_roll_link.STL"/>
    <mesh name="waist_yaw_link" file="waist_yaw_link.STL"/>
    <mesh name="waist_roll_link" file="waist_roll_link.STL"/>
    <mesh name="torso_link" file="torso_link.STL"/>
    <mesh name="logo_link" file="logo_link.STL"/>
    <mesh name="head_link" file="head_link.STL"/>
    <mesh name="waist_support_link" file="waist_support_link.STL"/>
    <mesh name="left_shoulder_pitch_link" file="left_shoulder_pitch_link.STL"/>
    <mesh name="left_shoulder_roll_link" file="left_shoulder_roll_link.STL"/>
    <mesh name="left_shoulder_yaw_link" file="left_shoulder_yaw_link.STL"/>
    <mesh name="left_elbow_link" file="left_elbow_link.STL"/>
    <mesh name="right_shoulder_pitch_link" file="right_shoulder_pitch_link.STL"/>
    <mesh name="right_shoulder_roll_link" file="right_shoulder_roll_link.STL"/>
    <mesh name="right_shoulder_yaw_link" file="right_shoulder_yaw_link.STL"/>
    <mesh name="right_elbow_link" file="right_elbow_link.STL"/>
  </asset>

  <worldbody>
    <geom name="floor" type="plane" conaffinity="2" size="100 100 .2" material="plane"/>

    <body name="pelvis" pos="0 0 0.795">
      <inertial pos="0 0 -0.0760301" quat="1 0 -0.000398273 0" mass="3.814" diaginertia="0.0105549 0.00931478 0.0079185"/>
      <joint name="floating_base_joint" type="free" limited="false" actuatorfrclimited="false"/>
      <geom type="mesh" contype="2" conaffinity="1" group="1" density="0" rgba="0.2 0.2 0.2 1" mesh="pelvis"/>
      <geom type="mesh" contype="2" conaffinity="1" group="1" density="0" rgba="0.7 0.7 0.7 1" mesh="pelvis_contour_link"/>
      <geom type="mesh" rgba="0.7 0.7 0.7 1" mesh="pelvis_contour_link"/>

      <site name='imu' size='0.01' pos='0.0 0 0.0' />

      <body name="left_hip_pitch_link" pos="0 0.064452 -0.1027">
        <inertial pos="0.002741 0.047791 -0.02606" quat="0.954862 0.293964 0.0302556 0.030122" mass="1.35" diaginertia="0.00181517 0.00153422 0.00116212"/>
        <joint name="left_hip_pitch_joint" pos="0 0 0" axis="0 1 0" range="-2.5307 2.8798" actuatorfrcrange="-88 88"/>
        <geom type="mesh" contype="2" conaffinity="1" group="1" density="0" rgba="0.2 0.2 0.2 1" mesh="left_hip_pitch_link"/>
        <geom type="mesh" rgba="0.2 0.2 0.2 1" mesh="left_hip_pitch_link"/>
        <body name="left_hip_roll_link" pos="0 0.052 -0.030465" quat="0.996179 0 -0.0873386 0">
          <inertial pos="0.029812 -0.001045 -0.087934" quat="0.977808 -1.97119e-05 0.205576 -0.0403793" mass="1.52" diaginertia="0.00254986 0.00241169 0.00148755"/>
          <joint name="left_hip_roll_joint" pos="0 0 0" axis="1 0 0" range="-0.5236 2.9671" actuatorfrcrange="-88 88"/>
          <geom type="mesh" contype="2" conaffinity="1" group="1" density="0" rgba="0.7 0.7 0.7 1" mesh="left_hip_roll_link"/>
          <geom type="mesh" rgba="0.7 0.7 0.7 1" mesh="left_hip_roll_link"/>
          <body name="left_hip_yaw_link" pos="0.025001 0 -0.12412">
            <inertial pos="-0.057709 -0.010981 -0.15078" quat="0.600598 0.15832 0.223482 0.751181" mass="1.702" diaginertia="0.00776166 0.00717575 0.00160139"/>
            <joint name="left_hip_yaw_joint" pos="0 0 0" axis="0 0 1" range="-2.7576 2.7576" actuatorfrcrange="-88 88"/>
            <geom type="mesh" contype="2" conaffinity="1" group="1" density="0" rgba="0.7 0.7 0.7 1" mesh="left_hip_yaw_link"/>
            <geom type="mesh" rgba="0.7 0.7 0.7 1" mesh="left_hip_yaw_link"/>
            <body name="left_knee_link" pos="-0.078273 0.0021489 -0.17734" quat="0.996179 0 0.0873386 0">
              <inertial pos="0.005457 0.003964 -0.12074" quat="0.923418 -0.0327699 0.0158246 0.382067" mass="1.932" diaginertia="0.0113804 0.0112778 0.00146458"/>
              <joint name="left_knee_joint" pos="0 0 0" axis="0 1 0" range="-0.087267 2.8798" actuatorfrcrange="-139 139"/>
              <geom type="mesh" contype="2" conaffinity="1" group="1" density="0" rgba="0.7 0.7 0.7 1" mesh="left_knee_link"/>
              <geom type="mesh" rgba="0.7 0.7 0.7 1" mesh="left_knee_link"/>
              <body name="left_ankle_pitch_link" pos="0 -9.4445e-05 -0.30001">
                <inertial pos="-0.007269 0 0.011137" quat="0.603053 0.369225 0.369225 0.603053" mass="0.074" diaginertia="1.89e-05 1.40805e-05 6.9195e-06"/>
                <joint name="left_ankle_pitch_joint" pos="0 0 0" axis="0 1 0" range="-0.87267 0.5236" actuatorfrcrange="-50 50"/>
                <geom type="mesh" contype="2" conaffinity="1" group="1" density="0" rgba="0.7 0.7 0.7 1" mesh="left_ankle_pitch_link"/>
                <geom type="mesh" rgba="0.7 0.7 0.7 1" mesh="left_ankle_pitch_link"/>
                <body name="left_ankle_roll_link" pos="0 0 -0.017558">
                  <inertial pos="0.026505 0 -0.016425" quat="-0.000481092 0.728482 -0.000618967 0.685065" mass="0.608" diaginertia="0.00167218 0.0016161 0.000217621"/>
                  <joint name="left_ankle_roll_joint" pos="0 0 0" axis="1 0 0" range="-0.2618 0.2618" actuatorfrcrange="-50 50"/>
                  <geom type="mesh" contype="2" conaffinity="1" group="1" density="0" rgba="0.2 0.2 0.2 1" mesh="left_ankle_roll_link"/>
                  <geom type="mesh" rgba="0.2 0.2 0.2 1" mesh="left_ankle_roll_link"/>
                </body>
              </body>
            </body>
          </body>
        </body>
      </body>
      <body name="right_hip_pitch_link" pos="0 -0.064452 -0.1027">
        <inertial pos="0.002741 -0.047791 -0.02606" quat="0.954862 -0.293964 0.0302556 -0.030122" mass="1.35" diaginertia="0.00181517 0.00153422 0.00116212"/>
        <joint name="right_hip_pitch_joint" pos="0 0 0" axis="0 1 0" range="-2.5307 2.8798" actuatorfrcrange="-88 88"/>
        <geom type="mesh" contype="2" conaffinity="1" group="1" density="0" rgba="0.2 0.2 0.2 1" mesh="right_hip_pitch_link"/>
        <geom type="mesh" rgba="0.2 0.2 0.2 1" mesh="right_hip_pitch_link"/>
        <body name="right_hip_roll_link" pos="0 -0.052 -0.030465" quat="0.996179 0 -0.0873386 0">
          <inertial pos="0.029812 0.001045 -0.087934" quat="0.977808 1.97119e-05 0.205576 0.0403793" mass="1.52" diaginertia="0.00254986 0.00241169 0.00148755"/>
          <joint name="right_hip_roll_joint" pos="0 0 0" axis="1 0 0" range="-2.9671 0.5236" actuatorfrcrange="-88 88"/>
          <geom type="mesh" contype="2" conaffinity="1" group="1" density="0" rgba="0.7 0.7 0.7 1" mesh="right_hip_roll_link"/>
          <geom type="mesh" rgba="0.7 0.7 0.7 1" mesh="right_hip_roll_link"/>
          <body name="right_hip_yaw_link" pos="0.025001 0 -0.12412">
            <inertial pos="-0.057709 0.010981 -0.15078" quat="0.751181 0.223482 0.15832 0.600598" mass="1.702" diaginertia="0.00776166 0.00717575 0.00160139"/>
            <joint name="right_hip_yaw_joint" pos="0 0 0" axis="0 0 1" range="-2.7576 2.7576" actuatorfrcrange="-88 88"/>
            <geom type="mesh" contype="2" conaffinity="1" group="1" density="0" rgba="0.7 0.7 0.7 1" mesh="right_hip_yaw_link"/>
            <geom type="mesh" rgba="0.7 0.7 0.7 1" mesh="right_hip_yaw_link"/>
            <body name="right_knee_link" pos="-0.078273 -0.0021489 -0.17734" quat="0.996179 0 0.0873386 0">
              <inertial pos="0.005457 -0.003964 -0.12074" quat="0.923439 0.0345276 0.0116333 -0.382012" mass="1.932" diaginertia="0.011374 0.0112843 0.00146452"/>
              <joint name="right_knee_joint" pos="0 0 0" axis="0 1 0" range="-0.087267 2.8798" actuatorfrcrange="-139 139"/>
              <geom type="mesh" contype="2" conaffinity="1" group="1" density="0" rgba="0.7 0.7 0.7 1" mesh="right_knee_link"/>
              <geom type="mesh" rgba="0.7 0.7 0.7 1" mesh="right_knee_link"/>
              <body name="right_ankle_pitch_link" pos="0 9.4445e-05 -0.30001">
                <inertial pos="-0.007269 0 0.011137" quat="0.603053 0.369225 0.369225 0.603053" mass="0.074" diaginertia="1.89e-05 1.40805e-05 6.9195e-06"/>
                <joint name="right_ankle_pitch_joint" pos="0 0 0" axis="0 1 0" range="-0.87267 0.5236" actuatorfrcrange="-50 50"/>
                <geom type="mesh" contype="2" conaffinity="1" group="1" density="0" rgba="0.7 0.7 0.7 1" mesh="right_ankle_pitch_link"/>
                <geom type="mesh" rgba="0.7 0.7 0.7 1" mesh="right_ankle_pitch_link"/>
                <body name="right_ankle_roll_link" pos="0 0 -0.017558">
                  <inertial pos="0.026505 0 -0.016425" quat="0.000481092 0.728482 0.000618967 0.685065" mass="0.608" diaginertia="0.00167218 0.0016161 0.000217621"/>
                  <joint name="right_ankle_roll_joint" pos="0 0 0" axis="1 0 0" range="-0.2618 0.2618" actuatorfrcrange="-50 50"/>
                  <geom type="mesh" contype="2" conaffinity="1" group="1" density="0" rgba="0.2 0.2 0.2 1" mesh="right_ankle_roll_link"/>
                  <geom type="mesh" rgba="0.2 0.2 0.2 1" mesh="right_ankle_roll_link"/>
                </body>
              </body>
            </body>
          </body>
        </body>
      </body>
      <body name="waist_yaw_link">
        <inertial pos="0.003964 0 0.018769" quat="-0.0178291 0.628464 0.0282471 0.777121" mass="0.244" diaginertia="0.000158561 0.000124229 9.67669e-05"/>
        <joint name="waist_yaw_joint" pos="0 0 0" axis="0 0 1" range="-2.618 2.618" actuatorfrcrange="-88 88"/>
        <geom type="mesh" contype="2" conaffinity="1" group="1" density="0" rgba="0.7 0.7 0.7 1" mesh="waist_yaw_link"/>
        <body name="waist_roll_link" pos="-0.0039635 0 0.035">
          <inertial pos="0 -0.000236 0.010111" quat="0.99979 0.020492 0 0" mass="0.047" diaginertia="7.515e-06 6.40206e-06 3.98394e-06"/>
          <joint name="waist_roll_joint" pos="0 0 0" axis="1 0 0" range="-0.52 0.52" actuatorfrcrange="-50 50"/>
          <geom type="mesh" contype="2" conaffinity="1" group="1" density="0" rgba="0.7 0.7 0.7 1" mesh="waist_roll_link"/>
          <body name="torso_link" pos="0 0 0.019">
            <inertial pos="0.00331672 0.000261479 0.179808" quat="0.999831 0.000374946 0.0179664 -0.00377662" mass="9.6" diaginertia="0.124179 0.11206 0.0325385"/>
            <joint name="waist_pitch_joint" pos="0 0 0" axis="0 1 0" range="-0.52 0.52" actuatorfrcrange="-50 50"/>
            <geom type="mesh" contype="2" conaffinity="1" group="1" density="0" rgba="0.7 0.7 0.7 1" mesh="torso_link"/>
            <geom type="mesh" rgba="0.7 0.7 0.7 1" mesh="torso_link"/>
            <geom pos="0.0039635 0 -0.054" quat="1 0 0 0" type="mesh" contype="2" conaffinity="1" group="1" density="0" rgba="0.2 0.2 0.2 1" mesh="logo_link"/>
            <geom pos="0.0039635 0 -0.054" quat="1 0 0 0" type="mesh" rgba="0.2 0.2 0.2 1" mesh="logo_link"/>
            <geom pos="0.0039635 0 -0.054" type="mesh" contype="2" conaffinity="1" group="1" density="0" rgba="0.2 0.2 0.2 1" mesh="head_link"/>
            <geom pos="0.0039635 0 -0.054" type="mesh" rgba="0.2 0.2 0.2 1" mesh="head_link"/>
            <geom pos="0.0039635 0 -0.054" quat="1 0 0 0" type="mesh" contype="2" conaffinity="1" group="1" density="0" rgba="0.7 0.7 0.7 1" mesh="waist_support_link"/>
            <geom pos="0.0039635 0 -0.054" quat="1 0 0 0" type="mesh" rgba="0.7 0.7 0.7 1" mesh="waist_support_link"/>
            <body name="left_shoulder_pitch_link" pos="0.0039563 0.10022 0.23778" quat="0.990264 0.139201 1.38722e-05 -9.86868e-05">
              <inertial pos="0 0.035892 -0.011628" quat="0.654152 0.0130458 -0.326267 0.68225" mass="0.718" diaginertia="0.000465864 0.000432842 0.000406394"/>
              <joint name="left_shoulder_pitch_joint" pos="0 0 0" axis="0 1 0" range="-3.0892 2.6704" actuatorfrcrange="-25 25"/>
              <geom type="mesh" contype="2" conaffinity="1" group="1" density="0" rgba="0.7 0.7 0.7 1" mesh="left_shoulder_pitch_link"/>
              <geom type="mesh" rgba="0.7 0.7 0.7 1" mesh="left_shoulder_pitch_link"/>
              <body name="left_shoulder_roll_link" pos="0 0.038 -0.013831" quat="0.990268 -0.139172 0 0">
                <inertial pos="-0.000227 0.00727 -0.063243" quat="0.701256 -0.0196223 -0.00710317 0.712604" mass="0.643" diaginertia="0.000691311 0.000618011 0.000388977"/>
                <joint name="left_shoulder_roll_joint" pos="0 0 0" axis="1 0 0" range="-1.5882 2.2515" actuatorfrcrange="-25 25"/>
                <geom type="mesh" contype="2" conaffinity="1" group="1" density="0" rgba="0.7 0.7 0.7 1" mesh="left_shoulder_roll_link"/>
                <geom type="mesh" rgba="0.7 0.7 0.7 1" mesh="left_shoulder_roll_link"/>
                <body name="left_shoulder_yaw_link" pos="0 0.00624 -0.1032">
                  <inertial pos="0.010773 -0.002949 -0.072009" quat="0.716879 -0.0964829 -0.0679942 0.687134" mass="0.734" diaginertia="0.00106187 0.00103217 0.000400661"/>
                  <joint name="left_shoulder_yaw_joint" pos="0 0 0" axis="0 0 1" range="-2.618 2.618" actuatorfrcrange="-25 25"/>
                  <geom type="mesh" contype="2" conaffinity="1" group="1" density="0" rgba="0.7 0.7 0.7 1" mesh="left_shoulder_yaw_link"/>
                  <geom type="mesh" rgba="0.7 0.7 0.7 1" mesh="left_shoulder_yaw_link"/>
                  <body name="left_elbow_link" pos="0.015783 0 -0.080518">
                    <inertial pos="0.064956 0.004454 -0.010062" quat="0.541765 0.636132 0.388821 0.388129" mass="0.6" diaginertia="0.000443035 0.000421612 0.000259353"/>
                    <joint name="left_elbow_joint" pos="0 0 0" axis="0 1 0" range="-1.0472 2.0944" actuatorfrcrange="-25 25"/>
                    <geom type="mesh" contype="2" conaffinity="1" group="1" density="0" rgba="0.7 0.7 0.7 1" mesh="left_elbow_link"/>
                    <geom type="mesh" rgba="0.7 0.7 0.7 1" mesh="left_elbow_link"/>
                  </body>
                </body>
              </body>
            </body>
            <body name="right_shoulder_pitch_link" pos="0.0039563 -0.10021 0.23778" quat="0.990264 -0.139201 1.38722e-05 9.86868e-05">
              <inertial pos="0 -0.035892 -0.011628" quat="0.68225 -0.326267 0.0130458 0.654152" mass="0.718" diaginertia="0.000465864 0.000432842 0.000406394"/>
              <joint name="right_shoulder_pitch_joint" pos="0 0 0" axis="0 1 0" range="-3.0892 2.6704" actuatorfrcrange="-25 25"/>
              <geom type="mesh" contype="2" conaffinity="1" group="1" density="0" rgba="0.7 0.7 0.7 1" mesh="right_shoulder_pitch_link"/>
              <geom type="mesh" rgba="0.7 0.7 0.7 1" mesh="right_shoulder_pitch_link"/>
              <body name="right_shoulder_roll_link" pos="0 -0.038 -0.013831" quat="0.990268 0.139172 0 0">
                <inertial pos="-0.000227 -0.00727 -0.063243" quat="0.712604 -0.00710317 -0.0196223 0.701256" mass="0.643" diaginertia="0.000691311 0.000618011 0.000388977"/>
                <joint name="right_shoulder_roll_joint" pos="0 0 0" axis="1 0 0" range="-2.2515 1.5882" actuatorfrcrange="-25 25"/>
                <geom type="mesh" contype="2" conaffinity="1" group="1" density="0" rgba="0.7 0.7 0.7 1" mesh="right_shoulder_roll_link"/>
                <geom type="mesh" rgba="0.7 0.7 0.7 1" mesh="right_shoulder_roll_link"/>
                <body name="right_shoulder_yaw_link" pos="0 -0.00624 -0.1032">
                  <inertial pos="0.010773 0.002949 -0.072009" quat="0.687134 -0.0679942 -0.0964829 0.716879" mass="0.734" diaginertia="0.00106187 0.00103217 0.000400661"/>
                  <joint name="right_shoulder_yaw_joint" pos="0 0 0" axis="0 0 1" range="-2.618 2.618" actuatorfrcrange="-25 25"/>
                  <geom type="mesh" contype="2" conaffinity="1" group="1" density="0" rgba="0.7 0.7 0.7 1" mesh="right_shoulder_yaw_link"/>
                  <geom type="mesh" rgba="0.7 0.7 0.7 1" mesh="right_shoulder_yaw_link"/>
                  <body name="right_elbow_link" pos="0.015783 0 -0.080518">
                    <inertial pos="0.064956 -0.004454 -0.010062" quat="0.388129 0.388821 0.636132 0.541765" mass="0.6" diaginertia="0.000443035 0.000421612 0.000259353"/>
                    <joint name="right_elbow_joint" pos="0 0 0" axis="0 1 0" range="-1.0472 2.0944" actuatorfrcrange="-25 25"/>
                    <geom type="mesh" contype="2" conaffinity="1" group="1" density="0" rgba="0.7 0.7 0.7 1" mesh="right_elbow_link"/>
                    <geom type="mesh" rgba="0.7 0.7 0.7 1" mesh="right_elbow_link"/>
                  </body>
                </body>
              </body>
            </body>
          </body>
        </body>
      </body>
    </body>
  </worldbody>

  <actuator>
    <motor name="left_hip_pitch_joint" joint="left_hip_pitch_joint"/>
    <motor name="left_hip_roll_joint" joint="left_hip_roll_joint"/>
    <motor name="left_hip_yaw_joint" joint="left_hip_yaw_joint"/>
    <motor name="left_knee_joint" joint="left_knee_joint"/>
    <motor name="left_ankle_pitch_joint" joint="left_ankle_pitch_joint"/>
    <motor name="left_ankle_roll_joint" joint="left_ankle_roll_joint"/>
    <motor name="right_hip_pitch_joint" joint="right_hip_pitch_joint"/>
    <motor name="right_hip_roll_joint" joint="right_hip_roll_joint"/>
    <motor name="right_hip_yaw_joint" joint="right_hip_yaw_joint"/>
    <motor name="right_knee_joint" joint="right_knee_joint"/>
    <motor name="right_ankle_pitch_joint" joint="right_ankle_pitch_joint"/>
    <motor name="right_ankle_roll_joint" joint="right_ankle_roll_joint"/>
    <motor name="waist_yaw_joint" joint="waist_yaw_joint"/>
    <motor name="waist_roll_joint" joint="waist_roll_joint"/>
    <motor name="waist_pitch_joint" joint="waist_pitch_joint"/>
    <motor name="left_shoulder_pitch_joint" joint="left_shoulder_pitch_joint"/>
    <motor name="left_shoulder_roll_joint" joint="left_shoulder_roll_joint"/>
    <motor name="left_shoulder_yaw_joint" joint="left_shoulder_yaw_joint"/>
    <motor name="left_elbow_joint" joint="left_elbow_joint"/>
    <motor name="right_shoulder_pitch_joint" joint="right_shoulder_pitch_joint"/>
    <motor name="right_shoulder_roll_joint" joint="right_shoulder_roll_joint"/>
    <motor name="right_shoulder_yaw_joint" joint="right_shoulder_yaw_joint"/>
    <motor name="right_elbow_joint" joint="right_elbow_joint"/>
  </actuator>

  <sensor>
    <!-- <actuatorpos name='Left_Leg_Joint1_p' actuator='Left_Leg_Joint1' user='13' />
    <actuatorpos name='Left_Leg_Joint2_p' actuator='Left_Leg_Joint2' user='13' />
    <actuatorpos name='Left_Leg_Joint3_p' actuator='Left_Leg_Joint3' user='13' />
    <actuatorpos name='Left_Leg_Joint4_p' actuator='Left_Leg_Joint4' user='13' />
    <actuatorpos name='Left_Leg_Joint5_p' actuator='Left_Leg_Joint5' user='13' />
    <actuatorpos name='Left_Leg_Joint6_p' actuator='Left_Leg_Joint6' user='13' />
    <actuatorpos name='Right_Leg_Joint1_p' actuator='Right_Leg_Joint1' user='13' />
    <actuatorpos name='Right_Leg_Joint2_p' actuator='Right_Leg_Joint2' user='13' />
    <actuatorpos name='Right_Leg_Joint3_p' actuator='Right_Leg_Joint3' user='13' />
    <actuatorpos name='Right_Leg_Joint4_p' actuator='Right_Leg_Joint4' user='13' />
    <actuatorpos name='Right_Leg_Joint5_p' actuator='Right_Leg_Joint5' user='13' />
    <actuatorpos name='Right_Leg_Joint6_p' actuator='Right_Leg_Joint6' user='13' />

    <actuatorvel name='Left_Leg_Joint1_v' actuator='Left_Leg_Joint1' user='13' />
    <actuatorvel name='Left_Leg_Joint2_v' actuator='Left_Leg_Joint2' user='13' />
    <actuatorvel name='Left_Leg_Joint3_v' actuator='Left_Leg_Joint3' user='13' />
    <actuatorvel name='Left_Leg_Joint4_v' actuator='Left_Leg_Joint4' user='13' />
    <actuatorvel name='Left_Leg_Joint5_v' actuator='Left_Leg_Joint5' user='13' />
    <actuatorvel name='Left_Leg_Joint6_v' actuator='Left_Leg_Joint6' user='13' />
    <actuatorvel name='Right_Leg_Joint1_v' actuator='Right_Leg_Joint1' user='13' />
    <actuatorvel name='Right_Leg_Joint2_v' actuator='Right_Leg_Joint2' user='13' />
    <actuatorvel name='Right_Leg_Joint3_v' actuator='Right_Leg_Joint3' user='13' />
    <actuatorvel name='Right_Leg_Joint4_v' actuator='Right_Leg_Joint4' user='13' />
    <actuatorvel name='Right_Leg_Joint5_v' actuator='Right_Leg_Joint5' user='13' />
    <actuatorvel name='Right_Leg_Joint6_v' actuator='Right_Leg_Joint6' user='13' />


    <actuatorfrc name='Left_Leg_Joint1_f' actuator='Left_Leg_Joint1' user='13' noise='1e-3' />
    <actuatorfrc name='Left_Leg_Joint2_f' actuator='Left_Leg_Joint2' user='13' noise='1e-3' />
    <actuatorfrc name='Left_Leg_Joint3_f' actuator='Left_Leg_Joint3' user='13' />
    <actuatorpos name='Left_Leg_Joint4_f' actuator='Left_Leg_Joint4' user='13' noise='1e-3' />
    <actuatorfrc name='Left_Leg_Joint5_f' actuator='Left_Leg_Joint5' user='13' noise='1e-3' />
    <actuatorfrc name='Left_Leg_Joint6_f' actuator='Left_Leg_Joint6' user='13' noise='1e-3' />
    <actuatorfrc name='Right_Leg_Joint1_f' actuator='Right_Leg_Joint1' user='13' noise='1e-3' />
    <actuatorfrc name='Right_Leg_Joint2_f' actuator='Right_Leg_Joint2' user='13' noise='1e-3' /> 
    <actuatorfrc name='Right_Leg_Joint3_f' actuator='Right_Leg_Joint3' user='13' />
    <actuatorpos name='Right_Leg_Joint4_f' actuator='Right_Leg_Joint4' user='13' noise='1e-3' />
    <actuatorfrc name='Right_Leg_Joint5_f' actuator='Right_Leg_Joint5' user='13' noise='1e-3' />
    <actuatorfrc name='Right_Leg_Joint6_f' actuator='Right_Leg_Joint6' user='13' noise='1e-3' /> -->



    <framequat name='orientation' objtype='site' noise='0.001' objname='imu' />
    <framepos name='position' objtype='site' noise='0.001' objname='imu' />
    <gyro name='angular-velocity' site='imu' noise='0.005' cutoff='34.9' />
    <velocimeter name='linear-velocity' site='imu' noise='0.001' cutoff='30' />
    <accelerometer name='linear-acceleration' site='imu' noise='0.005' cutoff='157' />
    <magnetometer name='magnetometer' site='imu' />

  </sensor>
</mujoco>